Workbook
Name 이름: '이름(명렬표)'!$A:$A

Sheet 문법유형
A1: 반 | B1: FO | E1: 반 | F1: Inter, AD | I1: 반 | J1: IVY
A2: 1 | B2: 객관식 | C2: 조동사 | E2: 1 | F2: 객관식 | G2: 부정사 | I2: 1 | J2: 객관식 | K2: 완료시제
A3: 2 | B3: 객관식 | C3: Be동사 | E3: 2 | F3: 객관식 | G3: 부정사 | I3: 2 | J3: 객관식 | K3: 완료시제
A4: 3 | B4: 객관식 | C4: 일반동사 | E4: 3 | F4: 객관식 | G4: 부정사 | I4: 3 | J4: 객관식 | K4: 완료시제
A5: 4 | B5: 객관식 | C5: 일반동사 | E5: 4 | F5: 객관식 | G5: 시제 | I5: 4 | J5: 객관식 | K5: 비교
A6: 5 | B6: 객관식 | C6: 일반동사 | E6: 5 | F6: 객관식 | G6: 부정사 | I6: 5 | J6: 객관식 | K6: 수동태
A7: 6 | B7: 객관식 | C7: 조동사 | E7: 6 | F7: 객관식 | G7: 동명사 | I7: 6 | J7: 객관식 | K7: 접속사
A8: 7 | B8: 객관식 | C8: Be동사 | E8: 7 | F8: 객관식 | G8: 동명사 | I8: 7 | J8: 객관식 | K8: 완료시제
A9: 8 | B9: 객관식 | C9: 일반동사 | E9: 8 | F9: 객관식 | G9: 동명사 | I9: 8 | J9: 객관식 | K9: 완료시제
A10: 9 | B10: 객관식 | C10: 조동사 | E10: 9 | F10: 객관식 | G10: 동명사 | I10: 9 | J10: 객관식 | K10: 수동태
A11: 10 | B11: 객관식 | C11: Be동사 | E11: 10 | F11: 객관식 | G11: 부정사 | I11: 10 | J11: 객관식 | K11: 비교
A12: 11 | B12: 객관식 | C12: 일반동사 | E12: 11 | F12: 객관식 | G12: 부정사 | I12: 11 | J12: 객관식 | K12: 비교
A13: 12 | B13: 객관식 | C13: 일반동사 | E13: 12 | F13: 객관식 | G13: 부정사 | I13: 12 | J13: 객관식 | K13: 접속사
... A31: 30 | B31: 주관식 | C31: 조동사 | E31: 30 | F31: 주관식 | G31: 동명사 | I31: 30 | J31: 주관식 | K31: 비교

Sheet 중1FO(문법주관식)
A1: 반 | B1: 이름 | C1: 26 | D1: 27 | E1: 28 | F1: 29 | G1: 30 | I1: 각 4점 만점에 부분점수 입력
A2: 1FO | B2: 조하린9866 | C2: 4 | D2: 4 | E2: 4 | F2: 4 | G2: 4 | H2: =SUM(C2:G2) -> 20
A3: 1FO | B3: 조이플4632 | C3: 2 | D3: 2 | E3: 2 | F3: 4 | G3: 4 | H3: =SUM(C3:G3) -> 14
A4: 1FO | B4: 한가인6162 | C4: 4 | D4: 2 | E4: 2 | F4: 4 | G4: 4 | H4: =SUM(C4:G4) -> 16
A5: 1FO | B5: 정준우7962 | C5: 4 | D5: 2 | E5: 2 | F5: 2 | G5: 4 | H5: =SUM(C5:G5) -> 14
A6: 1FO | B6: 김주하2492 | C6: 4 | D6: 2 | E6: 4 | F6: 2 | G6: 4 | H6: =SUM(C6:G6) -> 16
A7: 1FO | B7: 김상우2835 | C7: 4 | D7: 3 | E7: 2 | F7: 3 | G7: 2 | H7: =SUM(C7:G7) -> 14
A8: 1FO | B8: 심효주0430 | C8: 2 | D8: 2 | E8: 2 | F8: 2 | G8: 3 | H8: =SUM(C8:G8) -> 11
A9: 1FO | B9: 김유민0779 | C9: 4 | D9: 3 | E9: 3 | F9: 4 | G9: 3 | H9: =SUM(C9:G9) -> 17
A10: 1FO | B10: 이우진8720 | C10: 4 | D10: 4 | E10: 3 | F10: 2 | G10: 4 | H10: =SUM(C10:G10) -> 17
A11: 1FO | B11: 정유빈9239 | C11: 4 | D11: 3 | E11: 3 | F11: 4 | G11: 4 | H11: =SUM(C11:G11) -> 18
A12: 1FO | B12: 최아정6445 | C12: 4 | D12: 4 | E12: 4 | F12: 3 | G12: 4 | H12: =SUM(C12:G12) -> 19
A13: 1FO | B13: 오수진5052 | C13: 4 | D13: 3 | E13: 2 | F13: 2 | G13: 2 | H13: =SUM(C13:G13) -> 13
... A43: 1FO | B43: 정다율4243 | C43: 3 | D43: 3 | E43: 4 | F43: 4 | G43: 3 | H43: =SUM(C43:G43) -> 17

Sheet 중1INTER(문법주관식)
A1: 반 | B1: 이름 | C1: 26 | D1: 27 | E1: 28 | F1: 29 | G1: 30 | I1: 각 4점 만점에 부분점수 입력
A2: 1INT | B2: 이준희2280 | C2: 3 | D2: 4 | E2: 4 | F2: 3 | G2: 2 | H2: =SUM(C2:G2) -> 16
A3: 1INT | B3: 유주원4257 | C3: 4 | D3: 3 | E3: 4 | F3: 4 | G3: 3 | H3: =SUM(C3:G3) -> 18
A4: 1INT | B4: 신준우9838 | C4: 4 | D4: 3 | E4: 4 | F4: 4 | G4: 2 | H4: =SUM(C4:G4) -> 17
A5: 1INT | B5: 유태형0555 | C5: 3 | D5: 4 | E5: 4 | F5: 4 | G5: 3 | H5: =SUM(C5:G5) -> 18
A6: 1INT | B6: 오수빈0779 | C6: 4 | D6: 4 | E6: 4 | F6: 4 | G6: 2 | H6: =SUM(C6:G6) -> 18
A7: 1INT | B7: 권시윤4513 | C7: 3 | D7: 4 | E7: 4 | F7: 3 | G7: 4 | H7: =SUM(C7:G7) -> 18
A8: 1INT | B8: 추연우2028 | C8: 2 | D8: 4 | E8: 4 | F8: 2 | G8: 2 | H8: =SUM(C8:G8) -> 14
A9: 1INT | B9: 오준서1498 | C9: 3 | D9: 4 | E9: 4 | F9: 3 | G9: 2 | H9: =SUM(C9:G9) -> 16
A10: 1INT | B10: 손채은1360 | C10: 2 | D10: 2 | E10: 2 | F10: 4 | G10: 2 | H10: =SUM(C10:G10) -> 12
A11: 1INT | B11: 박하루1937 | C11: 3 | D11: 3 | E11: 4 | F11: 3 | G11: 3 | H11: =SUM(C11:G11) -> 16
A12: 1INT | B12: 정시안4023 | C12: 2 | D12: 4 | E12: 4 | F12: 4 | G12: 4 | H12: =SUM(C12:G12) -> 18
A13: 1INT | B13: 조성하2402 | C13: 0 | D13: 2 | E13: 4 | F13: 4 | G13: 2 | H13: =SUM(C13:G13) -> 12
... A21: 1INT | B21: 고은기8177 | C21: 2 | D21: 3 | E21: 4 | F21: 3 | G21: 3 | H21: =SUM(C21:G21) -> 15

Sheet 중1AD(문법주관식)
B1: 이름 | C1: 26 | D1: 27 | E1: 28 | F1: 29 | G1: 30
A2: 1AD | B2: 한준우9175 | C2: 2 | D2: 4 | E2: 4 | F2: 2 | G2: 2 | H2: =SUM(C2:G2) -> 14
A3: 1AD | B3: 장호진5446 | C3: 4 | D3: 4 | E3: 4 | F3: 4 | G3: 4 | H3: =SUM(C3:G3) -> 20
A4: 1AD | B4: 김서현1738 | C4: 4 | D4: 2 | E4: 4 | F4: 4 | G4: 2 | H4: =SUM(C4:G4) -> 16
A5: 1AD | B5: 김서연3408 | C5: 4 | D5: 2 | E5: 4 | F5: 4 | G5: 4 | H5: =SUM(C5:G5) -> 18
A6: 1AD | B6: 이채아0388 | C6: 4 | D6: 4 | E6: 4 | F6: 4 | G6: 0 | H6: =SUM(C6:G6) -> 16
A7: 1AD | B7: 김지우7486 | C7: 4 | D7: 4 | E7: 4 | F7: 2 | G7: 4 | H7: =SUM(C7:G7) -> 18
A8: 1AD | B8: 안채린0674 | C8: 4 | D8: 4 | E8: 4 | F8: 4 | G8: 4 | H8: =SUM(C8:G8) -> 20
A9: 1AD | B9: 남윤성2870 | C9: 4 | D9: 4 | E9: 4 | F9: 4 | G9: 3 | H9: =SUM(C9:G9) -> 19
A10: 1AD | B10: 박서현6242 | C10: 4 | D10: 4 | E10: 4 | F10: 4 | G10: 3 | H10: =SUM(C10:G10) -> 19
A11: 1AD | B11: 정유준0820 | C11: 4 | D11: 4 | E11: 4 | F11: 4 | G11: 4 | H11: =SUM(C11:G11) -> 20
A12: 1AD | B12: 김한서1381 | C12: 3 | D12: 3 | E12: 4 | F12: 4 | G12: 4 | H12: =SUM(C12:G12) -> 18
A13: 1AD | B13: 강지호1802 | C13: 4 | D13: 4 | E13: 4 | F13: 3 | G13: 4 | H13: =SUM(C13:G13) -> 19
... A29: 1AD | B29: 허은재1450 | C29: 2 | D29: 4 | E29: 4 | F29: 4 | G29: 3 | H29: =SUM(C29:G29) -> 17

Sheet 중1IVY(문법주관식)
A1: 반 | B1: 이름 | C1: 26 | D1: 27 | E1: 28 | F1: 29 | G1: 30 | I1: 각 4점 만점에 부분점수 입력
A2: IVY | B2: 이수민4482 | C2: 3 | D2: 4 | E2: 4 | F2: 4 | G2: 4 | H2: =SUM(C2:G2) -> 19
A3: IVY | B3: 구교석9155 | C3: 3 | D3: 4 | E3: 4 | F3: 4 | G3: 2 | H3: =SUM(C3:G3) -> 17
A4: IVY | B4: 이재인6956 | C4: 3 | D4: 4 | E4: 4 | F4: 4 | G4: 4 | H4: =SUM(C4:G4) -> 19
A5: IVY | B5: 김승연5446 | C5: 3 | D5: 4 | E5: 3 | F5: 3 | G5: 4 | H5: =SUM(C5:G5) -> 17
A6: IVY | B6: 오연서8335 | C6: 3 | D6: 4 | E6: 4 | F6: 4 | G6: 4 | H6: =SUM(C6:G6) -> 19
A7: IVY | B7: 이승현1373 | C7: 3 | D7: 4 | E7: 4 | F7: 4 | G7: 2 | H7: =SUM(C7:G7) -> 17
A8: IVY | B8: 이연서1743 | C8: 4 | D8: 4 | E8: 4 | F8: 4 | G8: 4 | H8: =SUM(C8:G8) -> 20
A9: IVY | B9: 장주원4149 | C9: 3 | D9: 4 | E9: 4 | F9: 4 | G9: 4 | H9: =SUM(C9:G9) -> 19

Sheet 중1FO(단어누적)
C1: 1 | D1: 2 | E1: 3 | F1: 4 | G1: 5 | H1: 6 | I1: 7 | J1: 8 | K1: 9 | L1: 10 | M1: 11 | N1: 12 | O1: 13 | P1: 14 | Q1: 15 | R1: 16 | S1: 17 | T1: 18 | U1: 19 | V1: 20 | W1: 21 | X1: 22
A2: 1FO | B2: 김민겸5784 | C2: 62 | D2: 62 | E2: 57 | F2: 57 | G2: 57 | H2: 57 | I2: 83 | J2: 83 | K2: 83 | L2: 83 | M2: 66 | N2: 66 | O2: 66 | P2: 66 | Q2: 78 | R2: 78 | S2: 78 | T2: 78 | U2: 75 | V2: 75 | W2: 75 | X2: 75
A3: 1FO | B3: 이석빈6231 | C3: 73 | D3: 73 | E3: 68 | F3: 68 | G3: 68 | H3: 68 | I3: 90 | J3: 90 | K3: 90 | L3: 90 | M3: 74 | N3: 74 | O3: 74 | P3: 74 | Q3: 86 | R3: 86 | S3: 86 | T3: 86 | U3: 80 | V3: 80 | W3: 80 | X3: 80
A4: 1FO | B4: 최건우1307 | C4: 63 | D4: 63 | E4: 67 | F4: 67 | G4: 67 | H4: 67 | I4: 결석 | J4: 결석 | K4: 결석 | L4: 결석 | M4: 결석 | N4: 결석 | O4: 결석 | P4: 결석 | Q4: 77 | R4: 77 | S4: 77 | T4: 77 | U4: 73 | V4: 73 | W4: 73 | X4: 73
A5: 1FO | B5: 조원서1079 | C5: 80 | D5: 80 | E5: 81 | F5: 81 | G5: 81 | H5: 81 | I5: 98 | J5: 98 | K5: 98 | L5: 98 | M5: 90 | N5: 90 | O5: 90 | P5: 90 | Q5: 92 | R5: 92 | S5: 92 | T5: 92 | U5: 92 | V5: 92 | W5: 92 | X5: 92
A6: 1FO | B6: 김지혁1126 | C6: 82 | D6: 82 | E6: 81 | F6: 81 | G6: 81 | H6: 81 | I6: 82 | J6: 82 | K6: 82 | L6: 82 | M6: 86 | N6: 86 | O6: 86 | P6: 86 | Q6: 88 | R6: 88 | S6: 88 | T6: 88 | U6: 90 | V6: 90 | W6: 90 | X6: 90
A7: 1FO | B7: 손유건0877 | C7: 67 | D7: 67 | E7: 77 | F7: 77 | G7: 77 | H7: 77 | I7: 96 | J7: 96 | K7: 96 | L7: 96 | M7: 94 | N7: 94 | O7: 94 | P7: 94 | Q7: 95 | R7: 95 | S7: 95 | T7: 95 | U7: 96 | V7: 96 | W7: 96 | X7: 96
A8: 1FO | B8: 정다율4243 | C8: 72 | D8: 72 | E8: 73 | F8: 73 | G8: 73 | H8: 73 | I8: 91 | J8: 91 | K8: 91 | L8: 91 | M8: 76 | N8: 76 | O8: 76 | P8: 76 | Q8: 74 | R8: 74 | S8: 74 | T8: 74 | U8: 76 | V8: 76 | W8: 76 | X8: 76
A9: 1FO | B9: 이예나4862 | C9: 77 | D9: 77 | E9: 85 | F9: 85 | G9: 85 | H9: 85 | I9: 94 | J9: 94 | K9: 94 | L9: 94 | M9: 84 | N9: 84 | O9: 84 | P9: 84 | Q9: 89 | R9: 89 | S9: 89 | T9: 89 | U9: 95 | V9: 95 | W9: 95 | X9: 95
A10: 1FO | B10: 김수현3124 | C10: 93 | D10: 93 | E10: 97 | F10: 97 | G10: 97 | H10: 97 | I10: 95 | J10: 95 | K10: 95 | L10: 95 | M10: 98 | N10: 98 | O10: 98 | P10: 98 | Q10: 98 | R10: 98 | S10: 98 | T10: 98 | U10: 97 | V10: 97 | W10: 97 | X10: 97
A11: 1FO | B11: 김지훈5106 | C11: 72 | D11: 72 | E11: 78 | F11: 78 | G11: 78 | H11: 78 | I11: 95 | J11: 95 | K11: 95 | L11: 95 | M11: 88 | N11: 88 | O11: 88 | P11: 88 | Q11: 90 | R11: 90 | S11: 90 | T11: 90 | U11: 83 | V11: 83 | W11: 83 | X11: 83
A12: 1FO | B12: 이민율5492 | C12: 82 | D12: 82 | E12: 76 | F12: 76 | G12: 76 | H12: 76 | I12: 89 | J12: 89 | K12: 89 | L12: 89 | M12: 83 | N12: 83 | O12: 83 | P12: 83 | Q12: 89 | R12: 89 | S12: 89 | T12: 89 | U12: 89 | V12: 89 | W12: 89 | X12: 89
A13: 1FO | B13: 최이삭8860 | C13: 88 | D13: 88 | E13: 90 | F13: 90 | G13: 90 | H13: 90 | I13: 87 | J13: 87 | K13: 87 | L13: 87 | M13: 87 | N13: 87 | O13: 87 | P13: 87 | Q13: 91 | R13: 91 | S13: 91 | T13: 91 | U13: 91 | V13: 91 | W13: 91 | X13: 91
A14: 1FO | B14: 김윤우4570 | C14: 92 | D14: 92 | E14: 81 | F14: 81 | G14: 81 | H14: 81 | I14: 88 | J14: 88 | K14: 88 | L14: 88 | M14: 90 | N14: 90 | O14: 90 | P14: 90 | Q14: 82 | R14: 82 | S14: 82 | T14: 82 | U14: 81 | V14: 81 | W14: 81 | X14: 81
A15: 1FO | B15: 임승준7363 | C15: 52 | D15: 52 | E15: 55 | F15: 55 | G15: 55 | H15: 55 | I15: 76 | J15: 76 | K15: 76 | L15: 76 | M15: 63 | N15: 63 | O15: 63 | P15: 63 | Q15: 60 | R15: 60 | S15: 60 | T15: 60 | U15: 결석 | V15: 결석 | W15: 결석 | X15: 결석
A16: 1FO | B16: 이다은3164 | C16: 100 | D16: 100 | E16: 55 | F16: 55 | G16: 55 | H16: 55 | I16: 100 | J16: 100 | K16: 100 | L16: 100 | M16: 98 | N16: 98 | O16: 98 | P16: 98 | Q16: 100 | R16: 100 | S16: 100 | T16: 100 | U16: 99 | V16: 99 | W16: 99 | X16: 99
A17: 1FO | B17: 최정우5267 | C17: 78.33 | D17: 78.33 | E17: 75 | F17: 75 | G17: 75 | H17: 75 | I17: 90 | J17: 90 | K17: 90 | L17: 90 | M17: 90 | N17: 90 | O17: 90 | P17: 90 | Q17: 86 | R17: 86 | S17: 86 | T17: 86 | U17: 90 | V17: 90 | W17: 90 | X17: 90
A18: 1FO | B18: 김은성1571 | E18: 84 | F18: 84 | G18: 84 | H18: 84 | I18: 99 | J18: 99 | K18: 99 | L18: 99 | M18: 92 | N18: 92 | O18: 92 | P18: 92 | Q18: 93 | R18: 93 | S18: 93 | T18: 93 | U18: 결석 | V18: 결석 | W18: 결석 | X18: 결석
A19: 1FO | B19: 김유민0779 | C19: 63.33 | D19: 63.33 | E19: 76 | F19: 76 | G19: 76 | H19: 76 | I19: 83 | J19: 83 | K19: 83 | L19: 83 | M19: 86 | N19: 86 | O19: 86 | P19: 86 | Q19: 86 | R19: 86 | S19: 86 | T19: 86 | U19: 87 | V19: 87 | W19: 87 | X19: 87
A20: 1FO | B20: 김상우2835 | C20: 66.67 | D20: 66.67 | E20: 72 | F20: 72 | G20: 72 | H20: 72 | I20: 82 | J20: 82 | K20: 82 | L20: 82 | M20: 71 | N20: 71 | O20: 71 | P20: 71 | Q20: 78 | R20: 78 | S20: 78 | T20: 78 | U20: 82 | V20: 82 | W20: 82 | X20: 82
A21: 1FO | B21: 이새롬1234 | C21: 90 | D21: 90 | E21: 84 | F21: 84 | G21: 84 | H21: 84 | I21: 91 | J21: 91 | K21: 91 | L21: 91 | M21: 90 | N21: 90 | O21: 90 | P21: 90 | Q21: 87 | R21: 87 | S21: 87 | T21: 87 | U21: 92 | V21: 92 | W21: 92 | X21: 92
A22: 1FO | B22: 이우진8720 | C22: 85 | D22: 85 | E22: 76 | F22: 76 | G22: 76 | H22: 76 | I22: 90 | J22: 90 | K22: 90 | L22: 90 | M22: 52 | N22: 52 | O22: 52 | P22: 52 | Q22: 79 | R22: 79 | S22: 79 | T22: 79 | U22: 56 | V22: 56 | W22: 56 | X22: 56
A23: 1FO | B23: 이시우1234 | C23: 93.33 | D23: 93.33 | E23: 95 | F23: 95 | G23: 95 | H23: 95 | I23: 99 | J23: 99 | K23: 99 | L23: 99 | M23: 99 | N23: 99 | O23: 99 | P23: 99 | Q23: 95 | R23: 95 | S23: 95 | T23: 95 | U23: 98 | V23: 98 | W23: 98 | X23: 98
A24: 1FO | B24: 오수진5052 | C24: 80 | D24: 80 | E24: 93 | F24: 93 | G24: 93 | H24: 93 | I24: 94 | J24: 94 | K24: 94 | L24: 94 | M24: 93 | N24: 93 | O24: 93 | P24: 93 | Q24: 93 | R24: 93 | S24: 93 | T24: 93 | U24: 96 | V24: 96 | W24: 96 | X24: 96
A25: 1FO | B25: 최아정6445 | C25: 100 | D25: 100 | E25: 97 | F25: 97 | G25: 97 | H25: 97 | I25: 92 | J25: 92 | K25: 92 | L25: 92 | M25: 97 | N25: 97 | O25: 97 | P25: 97 | Q25: 99 | R25: 99 | S25: 99 | T25: 99 | U25: 99 | V25: 99 | W25: 99 | X25: 99
A26: 1FO | B26: 정유빈9239 | C26: - | D26: 96 | E26: 99 | Q26: 96 | R26: 96 | S26: 96 | T26: 96 | U26: 99 | V26: 99 | W26: 99 | X26: 99
A27: 1FO | B27: 심효주0430 | C27: - | D27: 97 | E27: 77 | Q27: 97 | R27: 97 | S27: 97 | T27: 97 | U27: 77 | V27: 77 | W27: 77 | X27: 77
A28: 1FO | B28: 최은성6803 | M28: 64 | N28: 64 | O28: 64 | P28: 64 | Q28: 89 | R28: 89 | S28: 89 | T28: 89 | U28: 87 | V28: 87 | W28: 87 | X28: 87
A29: 1FO | B29: 남주원7734 | C29: 91.67 | D29: 91.67 | E29: 96.67 | F29: 96.67 | G29: 73.33 | H29: 73.33 | I29: 100 | J29: 100 | K29: 93.33 | L29: 93.33 | M29: 88.33 | N29: 88.33 | O29: 95 | P29: 95 | Q29: 88.33 | R29: 88.33 | S29: 86.67 | T29: 86.67 | U29: 86.67 | V29: 86.67 | W29: 93.33 | X29: 93.33
A30: 1FO | B30: 박현선8090 | C30: 30 | D30: 30 | E30: 76.67 | F30: 76.67 | G30: 26.67 | H30: 26.67 | I30: 56.67 | J30: 56.67 | K30: 63.33 | L30: 63.33 | M30: 50 | N30: 50 | O30: 58.33 | P30: 58.33 | Q30: 58.33 | R30: 58.33 | S30: 18.33 | T30: 18.33 | U30: 70 | V30: 70 | W30: 60 | X30: 60
A31: 1FO | B31: 송윤서1907 | C31: 73.33 | D31: 73.33 | E31: 100 | F31: 100 | G31: 80 | H31: 80 | I31: 96.67 | J31: 96.67 | K31: 90 | L31: 90 | M31: 98.33 | N31: 98.33 | O31: 93.33 | P31: 93.33 | Q31: 98.33 | R31: 98.33 | S31: 81.67 | T31: 81.67 | U31: 100 | V31: 100 | W31: 98.33 | X31: 98.33
A32: 1FO | B32: 송지유3134 | C32: 53.33 | D32: 53.33 | E32: 96.67 | F32: 96.67 | G32: 66.67 | H32: 66.67 | I32: 83.33 | J32: 83.33 | K32: 70 | L32: 70 | M32: 83.33 | N32: 83.33 | O32: 80 | P32: 80 | Q32: 63.33 | R32: 63.33 | S32: 63.33 | T32: 63.33 | U32: 96.67 | V32: 96.67 | W32: 85 | X32: 85
A33: 1FO | B33: 양준효5025 | C33: 30 | D33: 30 | E33: 56.67 | F33: 56.67 | G33: 40 | H33: 40 | I33: 88.33 | J33: 88.33 | K33: 41.67 | L33: 41.67 | M33: 36.67 | N33: 36.67 | O33: 28.33 | P33: 28.33 | Q33: 73.33 | R33: 73.33 | S33: 45 | T33: 45 | U33: 95 | V33: 95 | W33: 결석 | X33: 결석
A34: 1FO | B34: 조이플4632 | C34: 48.33 | D34: 48.33 | E34: 96.67 | F34: 96.67 | G34: 53.33 | H34: 53.33 | I34: 91.67 | J34: 91.67 | K34: 91.67 | L34: 91.67 | M34: 83.33 | N34: 83.33 | O34: 88.33 | P34: 88.33 | Q34: 53.33 | R34: 53.33 | S34: 80 | T34: 80 | U34: 86.67 | V34: 86.67 | W34: 76.67 | X34: 76.67
A35: 1FO | B35: 한가인6162 | C35: 61.67 | D35: 61.67 | E35: 91.67 | F35: 91.67 | G35: 53.33 | H35: 53.33 | I35: 100 | J35: 100 | K35: 100 | L35: 100 | M35: 95 | N35: 95 | O35: 90 | P35: 90 | Q35: 73.33 | R35: 73.33 | S35: 63.33 | T35: 63.33 | U35: 83.33 | V35: 83.33 | W35: 96.67 | X35: 96.67
A36: 1FO | B36: 정준우7962 | C36: 85 | D36: 85 | E36: 93.33 | F36: 93.33 | G36: 73.33 | H36: 73.33 | I36: 95 | J36: 95 | K36: 83.33 | L36: 83.33 | M36: 85 | N36: 85 | O36: 81.67 | P36: 81.67 | Q36: 85 | R36: 85 | S36: 86.67 | T36: 86.67 | U36: 86.67 | V36: 86.67 | W36: 81.67 | X36: 81.67
A37: 1FO | B37: 김예진0532 | I37: 93.33 | J37: 93.33 | K37: 90 | L37: 90 | M37: 85 | N37: 85 | O37: 85 | P37: 85 | Q37: 80 | R37: 80 | S37: 80 | T37: 80 | U37: 80 | V37: 80 | W37: 91.67 | X37: 91.67
A38: 1FO | B38: 황지민2281 | M38: 93.33 | N38: 93.33 | O38: 98.33 | P38: 98.33 | Q38: 96.67 | R38: 96.67 | S38: 95 | T38: 95 | U38: 98.33 | V38: 98.33 | W38: 95 | X38: 95
A39: 1FO | B39: 김주하2492 | M39: 88.33 | N39: 88.33 | Q39: 85 | R39: 85 | S39: 83.33 | T39: 83.33 | U39: 78.33 | V39: 78.33 | W39: 83.33 | X39: 83.33
A40: 1FO | B40: 조하린9866
...

Sheet 중1INTER(단어누적)
A1: 1IN | B1: 오준서1498 | C1: 68 | D1: 68 | E1: 87 | F1: 87 | G1: 87 | H1: 87 | I1: 81 | J1: 81 | K1: 81 | L1: 81 | Q1: 91 | R1: 91 | S1: 91 | T1: 91 | U1: 97 | V1: 97 | W1: 97 | X1: 97
A2: 1IN | B2: 조재인8304 | C2: 75 | D2: 75 | E2: 84 | F2: 84 | G2: 84 | H2: 84 | I2: 93 | J2: 93 | K2: 93 | L2: 93 | Q2: 89 | R2: 89 | S2: 89 | T2: 89 | U2: 86 | V2: 86 | W2: 86 | X2: 86
A3: 1IN | B3: 이선엽3390 | C3: 97 | D3: 97 | E3: 83 | F3: 83 | G3: 83 | H3: 83 | I3: 83 | J3: 83 | K3: 83 | L3: 83 | M3: 80 | N3: 80 | O3: 80 | P3: 80 | Q3: 80 | R3: 80 | S3: 80 | T3: 80 | U3: 81 | V3: 81 | W3: 81 | X3: 81
A4: 1IN | B4: 이서하1775 | C4: 98 | D4: 98 | E4: 81 | F4: 81 | G4: 81 | H4: 81 | I4: 80 | J4: 80 | K4: 80 | L4: 80 | M4: 85 | N4: 85 | O4: 85 | P4: 85 | Q4: 83 | R4: 83 | S4: 83 | T4: 83 | U4: 93 | V4: 93 | W4: 93 | X4: 93
A5: 1IN | B5: 고은기8177 | C5: 93 | D5: 93 | E5: 94 | F5: 94 | G5: 94 | H5: 94 | I5: 81 | J5: 81 | K5: 81 | L5: 81
A6: 1IN | B6: 박하율2672 | C6: 93 | D6: 93 | E6: 93 | F6: 93 | G6: 93 | H6: 93 | I6: 86 | J6: 86 | K6: 86 | L6: 86 | M6: 88 | N6: 88 | O6: 88 | P6: 88 | Q6: 91 | R6: 91 | S6: 91 | T6: 91 | U6: 87 | V6: 87 | W6: 87 | X6: 87
A7: 1IN | B7: 박하루1937 | C7: 75 | D7: 75 | E7: 80 | F7: 80 | G7: 80 | H7: 80 | I7: 84 | J7: 84 | K7: 84 | L7: 84 | M7: 78 | N7: 78 | O7: 78 | P7: 78 | Q7: 75 | R7: 75 | S7: 75 | T7: 75 | U7: 74 | V7: 74 | W7: 74 | X7: 74
A8: 1IN | B8: 유주원4257 | C8: 76.67 | D8: 76.67 | E8: 88 | F8: 88 | G8: 88 | H8: 88 | I8: 결석 | J8: 결석 | K8: 결석 | L8: 결석 | M8: 84 | N8: 84 | O8: 84 | P8: 84 | Q8: 79 | R8: 79 | S8: 79 | T8: 79 | U8: 73 | V8: 73 | W8: 73 | X8: 73
A9: 1IN | B9: 손채은1360 | C9: 95 | D9: 95 | E9: 98 | F9: 98 | G9: 98 | H9: 98 | I9: 100 | J9: 100 | K9: 100 | L9: 100 | M9: 99 | N9: 99 | O9: 99 | P9: 99 | Q9: 100 | R9: 100 | S9: 100 | T9: 100 | U9: 99 | V9: 99 | W9: 99 | X9: 99
A10: 1IN | B10: 권시윤4513 | C10: 56.67 | D10: 56.67 | E10: 82 | F10: 82 | G10: 82 | H10: 82 | I10: 89 | J10: 89 | K10: 89 | L10: 89 | M10: 80 | N10: 80 | O10: 80 | P10: 80 | Q10: 87 | R10: 87 | S10: 87 | T10: 87 | U10: 86 | V10: 86 | W10: 86 | X10: 86
A11: 1IN | B11: 이준희2280 | C11: 96.67 | D11: 96.67 | E11: 94 | F11: 94 | G11: 94 | H11: 94 | I11: 84 | J11: 84 | K11: 84 | L11: 84 | M11: 83 | N11: 83 | O11: 83 | P11: 83 | Q11: 93 | R11: 93 | S11: 93 | T11: 93 | U11: 87 | V11: 87 | W11: 87 | X11: 87
A12: 1IN | B12: 유태형0555 | C12: 83.33 | D12: 83.33 | E12: 82 | F12: 82 | G12: 82 | H12: 82 | I12: 90 | J12: 90 | K12: 90 | L12: 90 | M12: 87 | N12: 87 | O12: 87 | P12: 87 | Q12: 81 | R12: 81 | S12: 81 | T12: 81 | U12: 80 | V12: 80 | W12: 80 | X12: 80
A13: 1IN | B13: 신준우9838 | C13: 86.67 | D13: 86.67 | E13: 88 | F13: 88 | G13: 88 | H13: 88 | I13: 88 | J13: 88 | K13: 88 | L13: 88 | M13: 95 | N13: 95 | O13: 95 | P13: 95 | Q13: 87 | R13: 87 | S13: 87 | T13: 87 | U13: 87 | V13: 87 | W13: 87 | X13: 87
A14: 1IN | B14: 오수빈0779 | C14: 100 | D14: 100 | E14: 98 | F14: 98 | G14: 98 | H14: 98 | I14: 96 | J14: 96 | K14: 96 | L14: 96 | M14: 89 | N14: 89 | O14: 89 | P14: 89 | Q14: 90 | R14: 90 | S14: 90 | T14: 90 | U14: 96 | V14: 96 | W14: 96 | X14: 96
A15: 1IN | B15: 김도연2474 | C15: 86.67 | D15: 86.67 | E15: 88.33 | F15: 88.33 | G15: 88.33 | H15: 88.33 | I15: 86.67 | J15: 86.67 | K15: 결석 | L15: 결석 | M15: 75 | N15: 75 | O15: 91.67 | P15: 91.67 | Q15: 90 | R15: 90 | S15: 95 | T15: 지각 | U15: 68.33 | V15: 68.33 | W15: 83.33 | X15: 83.33
A16: 1IN | B16: 이주신6465 | C16: 66.67 | D16: 66.67 | E16: 결석 | F16: 결석 | G16: 68.33 | H16: 68.33 | I16: 41.67 | J16: 41.67 | K16: 53.33 | L16: 53.33 | M16: 16.67 | N16: 16.67 | O16: 71.67 | P16: 71.67 | Q16: 결석 | R16: 결석 | S16: 지각 | T16: 23.33 | U16: 30 | V16: 30 | W16: 21.67 | X16: 21.67
A17: 1IN | B17: 정시안4023 | C17: 95 | D17: 95 | E17: 95 | F17: 95 | G17: 93.33 | H17: 93.33 | I17: 98.33 | J17: 98.33 | K17: 98.33 | L17: 98.33 | M17: 88.33 | N17: 88.33 | O17: 100 | P17: 100 | Q17: 100 | R17: 100 | S17: 83.33 | T17: 95 | U17: 98.33 | V17: 98.33 | W17: 100 | X17: 100
A18: 1IN | B18: 추연우2028 | C18: 93.33 | D18: 93.33 | E18: 85 | F18: 85 | G18: 91.67 | H18: 91.67 | I18: 95 | J18: 95 | K18: 93.33 | L18: 93.33 | M18: 90 | N18: 90 | O18: 78.33 | P18: 78.33 | Q18: 95 | R18: 95 | S18: 83.33 | T18: 76.67 | U18: 68.33 | V18: 68.33 | W18: 85 | X18: 85
A19: 1IN | B19: 최이안3386 | C19: 86.67 | D19: 86.67 | E19: 95 | F19: 95 | G19: 100 | H19: 100 | I19: 100 | J19: 100 | K19: 100 | L19: 100 | M19: 93.33 | N19: 93.33 | O19: 100 | P19: 100 | Q19: 96.67 | R19: 96.67 | S19: 95 | T19: 96.67 | U19: 96.67 | V19: 96.67 | W19: 98.33 | X19: 98.33
A20: 1IN | B20: 조성하0222 | K20: 20 | L20: 20 | M20: 33.33 | N20: 33.33 | O20: 38.33 | P20: 38.33 | Q20: 25 | R20: 25 | S20: 31.67 | T20: 83.33 | U20: 75 | V20: 75 | W20: 33.33 | X20: 33.33
A21: 1IN | B21: 손채은1360 | T21: 75 | U21: 45 | V21: 45 | W21: 86.67 | X21: 86.67

Sheet 중1AD(단어누적)
A1: 1AD | B1: 김서연3408 | C1: 70 | D1: 70 | E1: 30 | F1: 30 | G1: 67.5 | H1: 67.5 | I1: 87.5 | J1: 87.5 | K1: 87.5 | L1: 87.5 | O1: 37.5 | P1: 37.5 | Q1: 72.5 | R1: 72.5 | S1: 55 | T1: 55 | U1: 93.75 | V1: 93.75 | W1: 72.5 | X1: 72.5
A2: 1AD | B2: 김서현1738 | C2: 70 | D2: 70 | E2: 76.25 | F2: 76.25 | G2: 71.25 | H2: 71.25 | I2: 90 | J2: 90 | K2: 88.75 | L2: 88.75 | M2: 43.75 | N2: 43.75 | O2: 52.5 | P2: 52.5 | Q2: 91.25 | R2: 91.25 | S2: 92.5 | T2: 92.5 | U2: 92.5 | V2: 92.5 | W2: 91.25 | X2: 91.25
A3: 1AD | B3: 이채아0388 | C3: 90 | D3: 90 | E3: 91.25 | F3: 91.25 | G3: 98.75 | H3: 98.75 | I3: 93.75 | J3: 93.75 | K3: 93.75 | L3: 93.75 | M3: 96.25 | N3: 96.25 | O3: 93.75 | P3: 93.75 | Q3: 96.25 | R3: 96.25 | S3: 97.5 | T3: 97.5 | U3: 95 | V3: 95 | W3: 96.25 | X3: 96.25
A4: 1AD | B4: 한준우9175 | C4: 51.25 | D4: 51.25 | E4: 87.5 | F4: 87.5 | G4: 48.75 | H4: 48.75 | I4: 88.75 | J4: 88.75 | K4: 58.75 | L4: 58.75 | M4: 80 | N4: 80 | O4: 40 | P4: 40 | Q4: 90 | R4: 90 | S4: 78.75 | T4: 78.75 | U4: 68.75 | V4: 68.75 | W4: 90 | X4: 90
A5: 1AD | B5: 안채린0674 | C5: 90 | D5: 90 | E5: 72.5 | F5: 72.5 | G5: 91.25 | H5: 91.25 | I5: 87.5 | J5: 87.5 | K5: 87.5 | L5: 87.5 | M5: 85 | N5: 85 | O5: 88.75 | P5: 88.75 | Q5: 90 | R5: 90 | S5: 96.25 | T5: 96.25 | U5: 92.5 | V5: 92.5 | W5: 90 | X5: 90
A6: 1AD | B6: 장호진5446 | E6: 90 | F6: 90 | G6: 98.75 | H6: 98.75 | I6: 100 | J6: 100 | K6: 100 | L6: 100 | M6: 100 | N6: 100 | O6: 100 | P6: 100 | Q6: 98.75 | R6: 98.75 | S6: 100 | T6: 100 | U6: 100 | V6: 100 | W6: 98.75 | X6: 98.75
A7: 1AD | B7: 김지우7486 | Q7: 40 | R7: 40 | S7: 93.75 | T7: 93.75 | U7: 98.75 | V7: 98.75 | W7: 40 | X7: 40
A8: 1AD | B8: 김지환4419 | C8: 97.5 | D8: 97.5 | E8: 85 | F8: 85 | G8: 85 | H8: 85 | I8: 78 | J8: 78 | K8: 78 | L8: 78 | M8: 93 | N8: 93 | O8: 93 | P8: 93 | Q8: 80 | R8: 80 | S8: 80 | T8: 80 | U8: 80 | V8: 80 | W8: 80 | X8: 80
A9: 1AD | B9: 김현성2425 | C9: 80 | D9: 80 | E9: 87 | F9: 87 | G9: 87 | H9: 87 | I9: 92 | J9: 92 | K9: 92 | L9: 92 | M9: 87 | N9: 87 | O9: 87 | P9: 87 | U9: 87 | V9: 87 | W9: 87 | X9: 87
A10: 1AD | B10: 성하은4160 | C10: 80 | D10: 80 | E10: 59 | F10: 59 | G10: 59 | H10: 59 | I10: 79 | J10: 79 | K10: 79 | L10: 79 | M10: 91 | N10: 91 | O10: 91 | P10: 91 | Q10: 87 | R10: 87 | S10: 87 | T10: 87 | U10: 81 | V10: 81 | W10: 81 | X10: 81
A11: 1AD | B11: 이현율7913 | C11: 60 | D11: 60 | E11: 43 | F11: 43 | G11: 43 | H11: 43 | I11: 69 | J11: 69 | K11: 69 | L11: 69 | M11: 82 | N11: 82 | O11: 82 | P11: 82 | Q11: 90 | R11: 90 | S11: 90 | T11: 90 | U11: 81 | V11: 81 | W11: 81 | X11: 81
A12: 1AD | B12: 강한별4082 | C12: 90 | D12: 90 | E12: 82 | F12: 82 | G12: 82 | H12: 82 | I12: 87 | J12: 87 | K12: 87 | L12: 87 | M12: 88 | N12: 88 | O12: 88 | P12: 88 | Q12: 89 | R12: 89 | S12: 89 | T12: 89 | U12: 88 | V12: 88 | W12: 88 | X12: 88
A13: 1AD | B13: 노은채5368 | C13: 86.25 | D13: 86.25 | E13: 67 | F13: 67 | G13: 67 | H13: 67 | I13: 74 | J13: 74 | K13: 74 | L13: 74 | M13: 89 | N13: 89 | O13: 89 | P13: 89 | Q13: 87 | R13: 87 | S13: 87 | T13: 87 | U13: 86 | V13: 86 | W13: 86 | X13: 86
A14: 1AD | B14: 김한서1381 | C14: 90 | D14: 90 | E14: 77 | F14: 77 | G14: 77 | H14: 77 | I14: 92 | J14: 92 | K14: 92 | L14: 92 | M14: 91 | N14: 91 | O14: 91 | P14: 91 | Q14: 92 | R14: 92 | S14: 92 | T14: 92 | U14: 90 | V14: 90 | W14: 90 | X14: 90
A15: 1AD | B15: 김혜원3364 | C15: 98.75 | D15: 98.75 | E15: 97 | F15: 97 | G15: 97 | H15: 97 | I15: 100 | J15: 100 | K15: 100 | L15: 100
A16: 1AD | B16: 이지안3502 | C16: 83.75 | D16: 83.75 | E16: 88 | F16: 88 | G16: 88 | H16: 88 | I16: 92 | J16: 92 | K16: 92 | L16: 92 | M16: 88 | N16: 88 | O16: 88 | P16: 88 | Q16: 90 | R16: 90 | S16: 90 | T16: 90 | U16: 88 | V16: 88 | W16: 88 | X16: 88
A17: 1AD | B17: 황기민8407 | C17: 98.75 | D17: 98.75 | E17: 83 | F17: 83 | G17: 83 | H17: 83 | I17: 97 | J17: 97 | K17: 97 | L17: 97
A18: 1AD | B18: 한해민1043 | C18: 95 | D18: 95 | E18: 87 | F18: 87 | G18: 87 | H18: 87 | I18: 92 | J18: 92 | K18: 92 | L18: 92 | M18: 84 | N18: 84 | O18: 84 | P18: 84 | Q18: 97 | R18: 97 | S18: 97 | T18: 97 | U18: 93 | V18: 93 | W18: 93 | X18: 93
A19: 1AD | B19: 김현민1263 | C19: 95 | D19: 95 | E19: 74 | F19: 74 | G19: 74 | H19: 74 | I19: 79 | J19: 79 | K19: 79 | L19: 79 | M19: - | N19: - | O19: - | P19: - | Q19: 90 | R19: 90 | S19: 90 | T19: 90 | U19: 92 | V19: 92 | W19: 92 | X19: 92
A20: 1AD | B20: 서윤솔8352 | C20: 98.75 | D20: 98.75 | E20: 93 | F20: 93 | G20: 93 | H20: 93 | I20: 94 | J20: 94 | K20: 94 | L20: 94 | M20: 94 | N20: 94 | O20: 94 | P20: 94 | U20: 94 | V20: 94 | W20: 94 | X20: 94
A21: 1AD | B21: 주민혁8678 | C21: 96.25 | D21: 96.25 | E21: 89 | F21: 89 | G21: 89 | H21: 89 | I21: 94 | J21: 94 | K21: 94 | L21: 94 | M21: 94 | N21: 94 | O21: 94 | P21: 94 | Q21: 87 | R21: 87 | S21: 87 | T21: 87 | U21: 96 | V21: 96 | W21: 96 | X21: 96
A22: 1AD | B22: 천성재8653 | C22: 95 | D22: 95 | E22: 90 | F22: 90 | G22: 90 | H22: 90 | I22: 94 | J22: 94 | K22: 94 | L22: 94 | M22: 96 | N22: 96 | O22: 96 | P22: 96 | Q22: 90 | R22: 90 | S22: 90 | T22: 90 | U22: 91 | V22: 91 | W22: 91 | X22: 91
A23: 1AD | B23: 김시우3538 | C23: 97.5 | D23: 97.5 | E23: 95 | F23: 95 | G23: 95 | H23: 95 | I23: 95 | J23: 95 | K23: 95 | L23: 95 | M23: - | N23: - | O23: - | P23: - | Q23: 97 | R23: 97 | S23: 97 | T23: 97 | U23: 93 | V23: 93 | W23: 93 | X23: 93
A24: 1AD | B24: 남윤성2870 | C24: 98.75 | D24: 98.75 | E24: 87 | F24: 87 | G24: 87 | H24: 87 | I24: 91 | J24: 91 | K24: 91 | L24: 91 | M24: 87 | N24: 87 | O24: 87 | P24: 87 | Q24: 85 | R24: 85 | S24: 85 | T24: 85 | U24: 87 | V24: 87 | W24: 87 | X24: 87
A25: 1AD | B25: 정유준0820 | C25: 87.5 | D25: 87.5 | E25: 93 | F25: 93 | G25: 93 | H25: 93 | I25: 96 | J25: 96 | K25: 96 | L25: 96 | M25: 88 | N25: 88 | O25: 88 | P25: 88 | Q25: 90 | R25: 90 | S25: 90 | T25: 90 | U25: 94 | V25: 94 | W25: 94 | X25: 94
A26: 1AD | B26: 허은재1450 | C26: 83.75 | D26: 83.75 | E26: 78 | F26: 78 | G26: 78 | H26: 78 | I26: 80 | J26: 80 | K26: 80 | L26: 80
A27: 1AD | B27: 강지호1802 | C27: 90 | D27: 90 | E27: 77 | F27: 77 | G27: 77 | H27: 77 | I27: 75 | J27: 75 | K27: 75 | L27: 75 | M27: 88 | N27: 88 | O27: 88 | P27: 88 | Q27: 76 | R27: 76 | S27: 76 | T27: 76 | U27: 85 | V27: 85 | W27: 85 | X27: 85
A28: 1AD | B28: 박서현6242 | C28: 86.25 | D28: 86.25 | E28: 80 | F28: 80 | G28: 80 | H28: 80 | I28: 79 | J28: 79 | K28: 79 | L28: 79 | M28: 88 | N28: 88 | O28: 88 | P28: 88 | Q28: 84 | R28: 84 | S28: 84 | T28: 84 | U28: 86 | V28: 86 | W28: 86 | X28: 86

Sheet 중1IVY(단어누적)
C1: 1 | D1: 2 | E1: 3 | F1: 4 | G1: 5 | H1: 6 | I1: 7 | J1: 8 | K1: 9 | L1: 10 | M1: 11 | N1: 12 | O1: 13 | P1: 14 | Q1: 15 | R1: 16 | S1: 17 | T1: 18 | U1: 19 | V1: 20 | W1: 21 | X1: 22
A2: 중1IVY | B2: 장주원4149 | C2: 97.5 | D2: 97.5 | E2: 99 | F2: 99 | G2: 99 | H2: 99 | I2: 95 | J2: 95 | K2: 95 | L2: 95 | M2: 96 | N2: 96 | O2: 96 | P2: 96 | Q2: 98 | R2: 98 | S2: 98 | T2: 98 | U2: 96 | V2: 96 | W2: 96 | X2: 96
A3: 중1IVY | B3: 오연서8335 | C3: 98.75 | D3: 98.75 | E3: 97 | F3: 97 | G3: 97 | H3: 97 | I3: 95 | J3: 95 | K3: 95 | L3: 95 | M3: 95 | N3: 95 | O3: 95 | P3: 95 | Q3: 98 | R3: 98 | S3: 98 | T3: 98 | U3: 93 | V3: 93 | W3: 93 | X3: 93
A4: 중1IVY | B4: 김승연5446 | C4: 98.75 | D4: 98.75 | E4: 92 | F4: 92 | G4: 92 | H4: 92 | I4: 90 | J4: 90 | K4: 90 | L4: 90 | M4: 82 | N4: 82 | O4: 82 | P4: 82 | Q4: 95 | R4: 95 | S4: 95 | T4: 95 | U4: 99 | V4: 99 | W4: 99 | X4: 99
A5: 중1IVY | B5: 이승현1373 | C5: 95 | D5: 95 | E5: 90 | F5: 90 | G5: 90 | H5: 90 | I5: 95 | J5: 95 | K5: 95 | L5: 95 | M5: 95 | N5: 95 | O5: 95 | P5: 95 | Q5: 93 | R5: 93 | S5: 93 | T5: 93
A6: 중1IVY | B6: 이예나3219 | C6: 결석 | D6: 결석 | E6: 85 | F6: 85 | G6: 85 | H6: 85 | I6: 87 | J6: 87 | K6: 87 | L6: 87 | M6: 88 | N6: 88 | O6: 88 | P6: 88 | Q6: 81 | R6: 81 | S6: 81 | T6: 81
A7: 중1IVY | B7: 김태린0735 | C7: 98.75 | D7: 98.75 | E7: 99 | F7: 99 | G7: 99 | H7: 99 | I7: 99 | J7: 99 | K7: 99 | L7: 99
A8: 중1IVY | B8: 이연서1743 | C8: 95 | D8: 95 | E8: 93 | F8: 93 | G8: 93 | H8: 93 | I8: 93 | J8: 93 | K8: 93 | L8: 93 | M8: 99 | N8: 99 | O8: 99 | P8: 99 | Q8: 89 | R8: 89 | S8: 89 | T8: 89 | U8: 98 | V8: 98 | W8: 98 | X8: 98
A9: 중1IVY | B9: 김정윤6658 | C9: 96.25 | D9: 96.25 | E9: 93 | F9: 93 | G9: 93 | H9: 93 | I9: 93 | J9: 93 | K9: 93 | L9: 93
A10: 중1IVY | B10: 이수민4482 | C10: 98.75 | D10: 98.75 | E10: 97 | F10: 97 | G10: 97 | H10: 97 | I10: 95 | J10: 95 | K10: 95 | L10: 95 | M10: 99 | N10: 99 | O10: 99 | P10: 99 | Q10: 92 | R10: 92 | S10: 92 | T10: 92 | U10: 98 | V10: 98 | W10: 98 | X10: 98
A11: 중1IVY | B11: 이윤찬 | C11: 92.5 | D11: 92.5 | E11: 83 | F11: 83 | G11: 83 | H11: 83 | I11: 90 | J11: 90 | K11: 90 | L11: 90
A12: 중1IVY | B12: 구교석9155 | C12: 100 | D12: 100 | E12: 100 | F12: 100 | G12: 100 | H12: 100 | I12: 99 | J12: 99 | K12: 99 | L12: 99 | M12: 96 | N12: 96 | O12: 96 | P12: 96 | Q12: 98 | R12: 98 | S12: 98 | T12: 98 | U12: 96 | V12: 96 | W12: 96 | X12: 96
A13: 중1IVY | B13: 이재인6956

Sheet 지침
A1: 1. 독해 점수 = (20문제를 70점 만점으로) + 30(기본점수) 2. 문법 점수 = 객관식(25문제, 각 2점) / 주관식(5문제 각 4점) + 30(기본점수) 3. 문법 유형성취도 (객관식 백분율 / 주관식 백분율) 4. 문법 영역성취도(객관식만 가지고 유형별로 백분율)

Sheet 이름(명렬표)
A2: 조하린9866 | B2: 1FO
A3: 조이플4632 | B3: 1FO
A4: 한가인6162 | B4: 1FO
A5: 정준우7962 | B5: 1FO
A6: 김주하2492 | B6: 1FO
A7: 김상우2835 | B7: 1FO
A8: 심효주0430 | B8: 1FO
A9: 김유민0779 | B9: 1FO
A10: 이우진8720 | B10: 1FO
A11: 정유빈9239 | B11: 1FO
A12: 최아정6445 | B12: 1FO
A13: 오수진5052 | B13: 1FO
... A99: 장주원4149 | B99: IVY

Sheet 성적표(상담용)
A2: 이름 | B2: 이수민4482 | D2: 반 | E2: =VLOOKUP(B2,'이름(명렬표)'!A2:B985,2,) -> IVY
F4: 진단평가 안내
F5: 이번시험은 3월과 4월에 공부했던 내용을 기반으로 출제했습니다. 문법의 경우 각 레벨에서 소화 해야 할 난이도의 문법을 출제했습니다. 영역별 성취도를 통해 추후 보강이 필요한 부분은 개별보강 할 예정입니다. 독해의 경우 그동안 공부한 지문이지만, 내신과 수능에서 만날수 있는 문제유형(주제, 제목, 내용일치, 추론)을 출제함으로, 글의 이해와 유형에 대한 연습을 목적으로 출제 하였습니다. 단어 결과는 정규 과정에서 공부한 단어의 누적 결과로 정규 단어 결과 + 주말 진행한 누적테스트의 결과 입니다.
C6: 문법 | D6: 독해
B7: =B2 -> 이수민4482 | C7: =VLOOKUP(B2,'중1(문법)'!$B$3:$AD$111,29,) -> 65 | D7: =VLOOKUP(B2,'중1(독해)'!$A$2:$G$107,7,) -> 82.5
B8: 반별평균 | C8: =VLOOKUP(E2,'중1(문법)'!$AF$2:$AG$5,2,) -> 58.333333 | D8: =VLOOKUP(E2,'중1(독해)'!$I$2:$J$5,2,) -> 77.4
C14: 문법 유형별 성취도 | F14: 문법 영역별 성취도
C15: 문법 | D15: 독해 | F15: =VLOOKUP(E2,'중1(문법)(영역별 성취도)'!$AG$3:$AK$6,2,) -> 완료시제 | G15: =VLOOKUP(E2,'중1(문법)(영역별 성취도)'!$AG$3:$AK$6,3,) -> 수동태 | H15: =VLOOKUP(E2,'중1(문법)(영역별 성취도)'!$AG$3:$AK$6,4,) -> 비교 | I15: =VLOOKUP(E2,'중1(문법)(영역별 성취도)'!$AG$3:$AK$6,5,) -> 접속사
C16: =VLOOKUP(B2,'중1(문법)'!$B$3:$AJ$111,34,) -> 0.92 | D16: =VLOOKUP(B2,'중1(문법)'!$B$3:$AJ$111,35,) -> 0.95 | F16: =VLOOKUP(B2,'중1(문법)(영역별 성취도)'!$B$3:$AF$111,28,) -> 0.66666667 | G16: =VLOOKUP(B2,'중1(문법)(영역별 성취도)'!$B$3:$AF$111,29,) -> 1 | H16: =VLOOKUP(B2,'중1(문법)(영역별 성취도)'!$B$3:$AF$111,30,) -> 1 | I16: =VLOOKUP(B2,'중1(문법)(영역별 성취도)'!$B$3:$AF$111,31,) -> 1
B23: 단어 누적 결과
B24: 1과 | C24: 2과 | D24: 3과 | E24: 4과 | F24: 5과 | G24: 6과 | H24: 7과 | I24: 8과 | J24: 9과 | K24: 10과 | L24: 11과 | M24: 12과 | N24: 13과 | O24: 14과 | P24: 15과 | Q24: 16과 | R24: 17과 | S24: 18과 | T24: 19과 | U24: 20과 | V24: 21과 | W24: 22과
B25: =VLOOKUP($B$2,'중1(단어누적)'!$B$1:$X$103,2,) -> 98.75 | C25: =VLOOKUP($B$2,'중1(단어누적)'!$B$1:$X$103,3,) -> 98.75 | D25: =VLOOKUP($B$2,'중1(단어누적)'!$B$1:$X$103,4,) -> 97 | E25: =VLOOKUP($B$2,'중1(단어누적)'!$B$1:$X$103,5,) -> 97 | F25: =VLOOKUP($B$2,'중1(단어누적)'!$B$1:$X$103,6,) -> 97 | G25: =VLOOKUP($B$2,'중1(단어누적)'!$B$1:$X$103,7,) -> 97 | H25: =VLOOKUP($B$2,'중1(단어누적)'!$B$1:$X$103,8,) -> 95 | I25: =VLOOKUP($B$2,'중1(단어누적)'!$B$1:$X$103,9,) -> 95 | J25: =VLOOKUP($B$2,'중1(단어누적)'!$B$1:$X$103,10,) -> 95 | K25: =VLOOKUP($B$2,'중1(단어누적)'!$B$1:$X$103,11,) -> 95 | L25: =VLOOKUP($B$2,'중1(단어누적)'!$B$1:$X$103,12,) -> 99 | M25: =VLOOKUP($B$2,'중1(단어누적)'!$B$1:$X$103,13,) -> 99 | N25: =VLOOKUP($B$2,'중1(단어누적)'!$B$1:$X$103,14,) -> 99 | O25: =VLOOKUP($B$2,'중1(단어누적)'!$B$1:$X$103,15,) -> 99 | P25: =VLOOKUP($B$2,'중1(단어누적)'!$B$1:$X$103,16,) -> 92 | Q25: =VLOOKUP($B$2,'중1(단어누적)'!$B$1:$X$103,17,) -> 92 | R25: =VLOOKUP($B$2,'중1(단어누적)'!$B$1:$X$103,18,) -> 92 | S25: =VLOOKUP($B$2,'중1(단어누적)'!$B$1:$X$103,19,) -> 92 | T25: =VLOOKUP($B$2,'중1(단어누적)'!$B$1:$X$103,20,) -> 98 | U25: =VLOOKUP($B$2,'중1(단어누적)'!$B$1:$X$103,21,) -> 98 | V25: =VLOOKUP($B$2,'중1(단어누적)'!$B$1:$X$103,22,) -> 98 | W25: =VLOOKUP($B$2,'중1(단어누적)'!$B$1:$X$103,23,) -> 98
B26: 12과 | C26: 13과 | D26: 14과 | E26: 15과 | F26: 16과 | G26: 17과 | H26: 18과 | I26: 19과 | J26: 20과 | K26: 21과 | L26: 22과
B27: =VLOOKUP($B$2,'중1(단어누적)'!$B$1:$X$103,13,) -> 99 | C27: =VLOOKUP($B$2,'중1(단어누적)'!$B$1:$X$103,14,) -> 99 | D27: =VLOOKUP($B$2,'중1(단어누적)'!$B$1:$X$103,15,) -> 99 | E27: =VLOOKUP($B$2,'중1(단어누적)'!$B$1:$X$103,16,) -> 92 | F27: =VLOOKUP($B$2,'중1(단어누적)'!$B$1:$X$103,17,) -> 92 | G27: =VLOOKUP($B$2,'중1(단어누적)'!$B$1:$X$103,18,) -> 92 | H27: =VLOOKUP($B$2,'중1(단어누적)'!$B$1:$X$103,19,) -> 92 | I27: =VLOOKUP($B$2,'중1(단어누적)'!$B$1:$X$103,20,) -> 98 | J27: =VLOOKUP($B$2,'중1(단어누적)'!$B$1:$X$103,21,) -> 98 | K27: =VLOOKUP($B$2,'중1(단어누적)'!$B$1:$X$103,22,) -> 98 | L27: =VLOOKUP($B$2,'중1(단어누적)'!$B$1:$X$103,23,) -> 98

Sheet 중1(문법)
C1: 조동사 | D1: Be동사 | E1: 일반동사 | F1: 일반동사 | G1: 일반동사 | H1: 조동사 | I1: Be동사 | J1: 일반동사 | K1: 조동사 | L1: Be동사 | M1: 일반동사 | N1: 일반동사 | O1: 일반동사 | P1: 일반동사 | Q1: 일반동사 | R1: 조동사 | S1: Be동사 | T1: 일반동사 | U1: 일반동사 | V1: 조동사 | W1: Be동사 | X1: 일반동사 | Y1: 일반동사 | Z1: 일반동사 | AA1: Be동사 | AF1: 평균
A2: 반 | B2: 이름 | C2: Q1 | D2: Q2 | E2: Q3 | F2: Q4 | G2: Q5 | H2: Q6 | I2: Q7 | J2: Q8 | K2: Q9 | L2: Q10 | M2: Q11 | N2: Q12 | O2: Q13 | P2: Q14 | Q2: Q15 | R2: Q16 | S2: Q17 | T2: Q18 | U2: Q19 | V2: Q20 | W2: Q21 | X2: Q22 | Y2: Q23 | Z2: Q24 | AA2: Q25 | AB2: 문법점수(객관식) | AC2: 문법점수(주관식) | AF2: 1FO | AG2: 52.5 | AI2: 문법 객관식 성취도 | AJ2: 문법 주관식 성취도
A3: 1FO | B3: 정다율4243 | C3: X | D3: O | E3: O | F3: O | G3: O | H3: O | I3: O | J3: O | K3: O | L3: O | M3: O | N3: O | O3: O | P3: O | Q3: X | R3: O | S3: X | T3: O | U3: O | V3: O | W3: X | X3: O | Y3: O | Z3: O | AA3: O | AB3: =(COUNTIF(C3:AA3,"O")*2) -> 42 | AC3: =VLOOKUP(B3,'중1FO(문법주관식)'!$B$2:$H$43,7,) -> 17 | AD3: =SUM(AB3:AC3) -> 59 | AF3: 1INT | AG3: 41.625 | AI3: =(AB3/50) -> 0.84 | AJ3: =(AC3/20) -> 0.85
A4: 1FO | B4: 최정우5267 | C4: O | D4: O | E4: O | F4: O | G4: O | H4: O | I4: O | J4: O | K4: X | L4: O | M4: O | N4: O | O4: O | P4: O | Q4: O | R4: O | S4: O | T4: O | U4: O | V4: X | W4: O | X4: X | Y4: O | Z4: X | AA4: X | AB4: =(COUNTIF(C4:AA4,"O")*2) -> 40 | AC4: =VLOOKUP(B4,'중1FO(문법주관식)'!$B$2:$H$43,7,) -> 18 | AD4: =SUM(AB4:AC4) -> 58 | AF4: 1AD | AG4: 54.535714 | AI4: =(AB4/50) -> 0.8 | AJ4: =(AC4/20) -> 0.9
A5: 1FO | B5: 조하린9866 | C5: O | D5: X | E5: O | F5: O | G5: O | H5: O | I5: O | J5: O | K5: O | L5: O | M5: O | N5: O | O5: O | P5: O | Q5: O | R5: O | S5: X | T5: O | U5: O | V5: O | W5: O | X5: X | Y5: O | Z5: O | AA5: O | AB5: =(COUNTIF(C5:AA5,"O")*2) -> 44 | AC5: =VLOOKUP(B5,'중1FO(문법주관식)'!$B$2:$H$43,7,) -> 20 | AD5: =SUM(AB5:AC5) -> 64 | AF5: IVY | AG5: 58.333333 | AI5: =(AB5/50) -> 0.88 | AJ5: =(AC5/20) -> 1
A6: 1FO | B6: 조이플4632 | C6: X | D6: X | E6: X | F6: O | G6: O | H6: O | I6: O | J6: X | K6: O | L6: X | M6: O | N6: O | O6: O | P6: O | Q6: O | R6: O | S6: O | T6: X | U6: O | V6: O | W6: O | X6: X | Y6: O | Z6: O | AA6: O | AB6: =(COUNTIF(C6:AA6,"O")*2) -> 36 | AC6: =VLOOKUP(B6,'중1FO(문법주관식)'!$B$2:$H$43,7,) -> 14 | AD6: =SUM(AB6:AC6) -> 50 | AI6: =(AB6/50) -> 0.72 | AJ6: =(AC6/20) -> 0.7
A7: 1FO | B7: 한가인6162 | C7: O | D7: O | E7: O | F7: O | G7: O | H7: O | I7: O | J7: O | K7: O | L7: O | M7: O | N7: O | O7: O | P7: O | Q7: X | R7: O | S7: X | T7: O | U7: O | V7: O | W7: O | X7: O | Y7: X | Z7: X | AA7: X | AB7: =(COUNTIF(C7:AA7,"O")*2) -> 40 | AC7: =VLOOKUP(B7,'중1FO(문법주관식)'!$B$2:$H$43,7,) -> 16 | AD7: =SUM(AB7:AC7) -> 56 | AI7: =(AB7/50) -> 0.8 | AJ7: =(AC7/20) -> 0.8
A8: 1FO | B8: 정준우7962 | C8: O | D8: O | E8: O | F8: O | G8: O | H8: O | I8: O | J8: O | K8: O | L8: O | M8: O | N8: O | O8: O | P8: O | Q8: O | R8: O | S8: O | T8: O | U8: O | V8: O | W8: O | X8: O | Y8: X | Z8: O | AA8: X | AB8: =(COUNTIF(C8:AA8,"O")*2) -> 46 | AC8: =VLOOKUP(B8,'중1FO(문법주관식)'!$B$2:$H$43,7,) -> 14 | AD8: =SUM(AB8:AC8) -> 60 | AI8: =(AB8/50) -> 0.92 | AJ8: =(AC8/20) -> 0.7
A9: 1FO | B9: 김주하2492 | C9: O | D9: O | E9: O | F9: O | G9: O | H9: O | I9: O | J9: O | K9: O | L9: O | M9: O | N9: O | O9: X | P9: O | Q9: O | R9: O | S9: O | T9: X | U9: O | V9: O | W9: O | X9: X | Y9: O | Z9: X | AA9: O | AB9: =(COUNTIF(C9:AA9,"O")*2) -> 42 | AC9: =VLOOKUP(B9,'중1FO(문법주관식)'!$B$2:$H$43,7,) -> 16 | AD9: =SUM(AB9:AC9) -> 58 | AI9: =(AB9/50) -> 0.84 | AJ9: =(AC9/20) -> 0.8
A10: 1FO | B10: 김상우2835 | C10: X | D10: O | E10: O | F10: O | G10: O | H10: X | I10: O | J10: X | K10: O | L10: X | M10: O | N10: O | O10: O | P10: O | Q10: X | R10: X | S10: X | T10: X | U10: X | V10: O | W10: O | X10: O | Y10: X | Z10: X | AA10: O | AB10: =(COUNTIF(C10:AA10,"O")*2) -> 28 | AC10: =VLOOKUP(B10,'중1FO(문법주관식)'!$B$2:$H$43,7,) -> 14 | AD10: =SUM(AB10:AC10) -> 42 | AI10: =(AB10/50) -> 0.56 | AJ10: =(AC10/20) -> 0.7
A11: 1FO | B11: 심효주0430 | C11: X | D11: X | E11: X | F11: X | G11: X | H11: O | I11: O | J11: X | K11: X | L11: O | M11: O | N11: O | O11: X | P11: X | Q11: X | R11: O | S11: X | T11: X | U11: X | V11: X | W11: X | X11: X | Y11: O | Z11: X | AA11: X | AB11: =(COUNTIF(C11:AA11,"O")*2) -> 14 | AC11: =VLOOKUP(B11,'중1FO(문법주관식)'!$B$2:$H$43,7,) -> 11 | AD11: =SUM(AB11:AC11) -> 25 | AI11: =(AB11/50) -> 0.28 | AJ11: =(AC11/20) -> 0.55
A12: 1FO | B12: 김유민0779 | C12: O | D12: O | E12: O | F12: O | G12: O | H12: O | I12: O | J12: O | K12: X | L12: O | M12: O | N12: O | O12: O | P12: O | Q12: O | R12: O | S12: X | T12: X | U12: O | V12: X | W12: O | X12: X | Y12: O | Z12: X | AA12: O | AB12: =(COUNTIF(C12:AA12,"O")*2) -> 38 | AC12: =VLOOKUP(B12,'중1FO(문법주관식)'!$B$2:$H$43,7,) -> 17 | AD12: =SUM(AB12:AC12) -> 55 | AI12: =(AB12/50) -> 0.76 | AJ12: =(AC12/20) -> 0.85
A13: 1FO | B13: 이우진8720 | C13: X | D13: O | E13: O | F13: O | G13: O | H13: O | I13: O | J13: O | K13: X | L13: O | M13: O | N13: O | O13: O | P13: O | Q13: X | R13: X | S13: O | T13: X | U13: O | V13: O | W13: O | X13: X | Y13: X | Z13: X | AA13: O | AB13: =(COUNTIF(C13:AA13,"O")*2) -> 34 | AC13: =VLOOKUP(B13,'중1FO(문법주관식)'!$B$2:$H$43,7,) -> 17 | AD13: =SUM(AB13:AC13) -> 51 | AI13: =(AB13/50) -> 0.68 | AJ13: =(AC13/20) -> 0.85
A14: 1FO | B14: 정유빈9239 | C14: O | D14: O | E14: O | F14: O | G14: O | H14: O | I14: O | J14: O | K14: X | L14: O | M14: O | N14: O | O14: O | P14: X | Q14: X | R14: O | S14: O | T14: X | U14: O | V14: O | W14: O | X14: O | Y14: X | Z14: O | AA14: X | AB14: =(COUNTIF(C14:AA14,"O")*2) -> 38 | AC14: =VLOOKUP(B14,'중1FO(문법주관식)'!$B$2:$H$43,7,) -> 18 | AD14: =SUM(AB14:AC14) -> 56 | AI14: =(AB14/50) -> 0.76 | AJ14: =(AC14/20) -> 0.9
A15: 1FO | B15: 최아정6445 | C15: O | D15: O | E15: O | F15: O | G15: O | H15: O | I15: O | J15: O | K15: O | L15: O | M15: O | N15: O | O15: O | P15: O | Q15: O | R15: O | S15: O | T15: O | U15: O | V15: O | W15: O | X15: X | Y15: O | Z15: O | AA15: O | AB15: =(COUNTIF(C15:AA15,"O")*2) -> 48 | AC15: =VLOOKUP(B15,'중1FO(문법주관식)'!$B$2:$H$43,7,) -> 19 | AD15: =SUM(AB15:AC15) -> 67 | AI15: =(AB15/50) -> 0.96 | AJ15: =(AC15/20) -> 0.95
A16: 1FO | B16: 오수진5052 | C16: O | D16: X | E16: O | F16: O | G16: O | H16: X | I16: X | J16: O | K16: X | L16: X | M16: O | N16: O | O16: X | P16: O | Q16: X | R16: O | S16: X | T16: X | U16: X | V16: O | W16: X | X16: X | Y16: O | Z16: O | AA16: O | AB16: =(COUNTIF(C16:AA16,"O")*2) -> 26 | AC16: =VLOOKUP(B16,'중1FO(문법주관식)'!$B$2:$H$43,7,) -> 13 | AD16: =SUM(AB16:AC16) -> 39 | AI16: =(AB16/50) -> 0.52 | AJ16: =(AC16/20) -> 0.65
A17: 1FO | B17: 이시우1234 | C17: O | D17: O | E17: O | F17: O | G17: O | H17: O | I17: O | J17: O | K17: X | L17: O | M17: O | N17: O | O17: O | P17: O | Q17: X | R17: O | S17: O | T17: O | U17: O | V17: O | W17: O | X17: O | Y17: X | Z17: O | AA17: O | AB17: =(COUNTIF(C17:AA17,"O")*2) -> 44 | AC17: =VLOOKUP(B17,'중1FO(문법주관식)'!$B$2:$H$43,7,) -> 16 | AD17: =SUM(AB17:AC17) -> 60 | AI17: =(AB17/50) -> 0.88 | AJ17: =(AC17/20) -> 0.8
... A43: 1FO | B43: 하이준1299 | C43: X | D43: O | E43: O | F43: O | G43: O | H43: O | I43: O | J43: O | K43: O | L43: O | M43: O | N43: O | O43: X | P43: O | Q43: O | R43: X | S43: X | T43: X | U43: O | V43: O | W43: X | X43: O | Y43: X | Z43: X | AA43: X | AB43: =(COUNTIF(C43:AA43,"O")*2) -> 32 | AC43: =VLOOKUP(B43,'중1FO(문법주관식)'!$B$2:$H$43,7,) -> 12 | AD43: =SUM(AB43:AC43) -> 44 | AI43: =(AB43/50) -> 0.64 | AJ43: =(AC43/20) -> 0.6
A44: 1FO | B44: 최황지7291 | C44: O | D44: O | E44: O | F44: O | G44: O | H44: O | I44: O | J44: O | K44: X | L44: X | M44: O | N44: O | O44: O | P44: O | Q44: X | R44: O | S44: X | T44: X | U44: O | V44: O | W44: X | X44: X | Y44: O | Z44: X | AA44: O | AB44: =(COUNTIF(C44:AA44,"O")*2) -> 34 | AC44: =VLOOKUP(B44,'중1FO(문법주관식)'!$B$2:$H$43,7,) -> 10 | AD44: =SUM(AB44:AC44) -> 44 | AE44: =AVERAGE(AD3:AD44) -> 52.5 | AI44: =(AB44/50) -> 0.68 | AJ44: =(AC44/20) -> 0.5
C46: 부정사 | D46: 부정사 | E46: 부정사 | F46: 시제 | G46: 부정사 | H46: 동명사 | I46: 동명사 | J46: 동명사 | K46: 동명사 | L46: 부정사 | M46: 부정사 | N46: 부정사 | O46: 부정사 | P46: 동명사 | Q46: 시제 | R46: 시제 | S46: 부정사 | T46: 부정사 | U46: 동명사 | V46: 시제 | W46: 시제 | X46: 부정사 | Y46: 부정사 | Z46: 시제 | AA46: 부정사
A47: 1INT | B47: 손지원1266 | C47: O | D47: O | E47: O | F47: O | G47: O | H47: O | I47: O | J47: O | K47: O | L47: O | M47: O | N47: X | O47: O | P47: O | Q47: O | R47: O | S47: O | T47: O | U47: O | V47: O | W47: O | X47: O | Y47: O | Z47: O | AA47: O | AB47: =(COUNTIF(C47:AA47,"O")*2) -> 48 | AC47: 내일 점수 확인해야 함 | AD47: =SUM(AB47:AC47) -> 48 | AI47: =(AB47/50) -> 0.96 | AJ47: =(AC47/20) -> #VALUE!
A48: 1INT | B48: 이윤오2947 | C48: X | D48: X | E48: X | F48: O | G48: O | H48: O | I48: O | J48: O | K48: X | L48: O | M48: O | N48: O | O48: X | P48: X | Q48: X | R48: X | S48: O | T48: O | U48: O | V48: X | W48: O | X48: X | Y48: X | Z48: O | AA48: X | AB48: =(COUNTIF(C48:AA48,"O")*2) -> 26 | AC48: 내일 점수 확인해야 함 | AD48: =SUM(AB48:AC48) -> 26 | AI48: =(AB48/50) -> 0.52 | AJ48: =(AC48/20) -> #VALUE!
A49: 1INT | B49: 손현겸3726 | C49: X | D49: X | E49: X | F49: O | G49: O | H49: O | I49: X | J49: O | K49: O | L49: X | M49: O | N49: X | O49: O | P49: O | Q49: O | R49: X | S49: O | T49: O | U49: X | V49: X | W49: O | X49: X | Y49: X | Z49: O | AA49: X | AB49: =(COUNTIF(C49:AA49,"O")*2) -> 26 | AC49: 내일 점수 확인해야 함 | AD49: =SUM(AB49:AC49) -> 26 | AI49: =(AB49/50) -> 0.52 | AJ49: =(AC49/20) -> #VALUE!
A50: 1INT | B50: 이소영6515 | C50: X | D50: X | E50: X | F50: X | G50: O | H50: O | I50: O | J50: X | K50: O | L50: O | M50: X | N50: X | O50: X | P50: X | Q50: X | R50: X | S50: O | T50: O | U50: O | V50: X | W50: O | X50: O | Y50: O | Z50: O | AA50: O | AB50: =(COUNTIF(C50:AA50,"O")*2) -> 26 | AC50: 내일 점수 확인해야 함 | AD50: =SUM(AB50:AC50) -> 26 | AI50: =(AB50/50) -> 0.52 | AJ50: =(AC50/20) -> #VALUE!
A51: 1INT | B51: 이준희2280 | C51: O | D51: X | E51: X | F51: X | G51: X | H51: O | I51: X | J51: X | K51: X | L51: O | M51: X | N51: O | O51: X | P51: X | Q51: O | R51: X | S51: O | T51: X | U51: X | V51: O | W51: X | X51: X | Y51: X | Z51: O | AA51: X | AB51: =(COUNTIF(C51:AA51,"O")*2) -> 16 | AC51: =VLOOKUP(B51,'중1INTER(문법주관식)'!$B$2:$H$21,7,) -> 16 | AD51: =SUM(AB51:AC51) -> 32 | AI51: =(AB51/50) -> 0.32 | AJ51: =(AC51/20) -> 0.8
A52: 1INT | B52: 유주원4257 | C52: X | D52: X | E52: O | F52: O | G52: O | H52: O | I52: O | J52: O | K52: O | L52: O | M52: O | N52: O | O52: X | P52: O | Q52: X | R52: O | S52: O | T52: O | U52: O | V52: X | W52: O | X52: X | Y52: O | Z52: O | AA52: O | AB52: =(COUNTIF(C52:AA52,"O")*2) -> 38 | AC52: =VLOOKUP(B52,'중1INTER(문법주관식)'!$B$2:$H$21,7,) -> 18 | AD52: =SUM(AB52:AC52) -> 56 | AI52: =(AB52/50) -> 0.76 | AJ52: =(AC52/20) -> 0.9
A53: 1INT | B53: 신준우9838 | C53: O | D53: X | E53: O | F53: X | G53: O | H53: O | I53: O | J53: X | K53: X | L53: O | M53: O | N53: X | O53: O | P53: O | Q53: X | R53: O | S53: O | T53: X | U53: O | V53: X | W53: O | X53: X | Y53: O | Z53: O | AA53: X | AB53: =(COUNTIF(C53:AA53,"O")*2) -> 30 | AC53: =VLOOKUP(B53,'중1INTER(문법주관식)'!$B$2:$H$21,7,) -> 17 | AD53: =SUM(AB53:AC53) -> 47 | AI53: =(AB53/50) -> 0.6 | AJ53: =(AC53/20) -> 0.85
A54: 1INT | B54: 유태형0555 | C54: X | D54: X | E54: O | F54: O | G54: O | H54: O | I54: O | J54: O | K54: X | L54: O | M54: O | N54: X | O54: O | P54: X | Q54: O | R54: X | S54: X | T54: O | U54: O | V54: X | W54: O | X54: X | Y54: X | Z54: O | AA54: X | AB54: =(COUNTIF(C54:AA54,"O")*2) -> 28 | AC54: =VLOOKUP(B54,'중1INTER(문법주관식)'!$B$2:$H$21,7,) -> 18 | AD54: =SUM(AB54:AC54) -> 46 | AI54: =(AB54/50) -> 0.56 | AJ54: =(AC54/20) -> 0.9
A55: 1INT | B55: 오수빈0779 | C55: X | D55: X | E55: O | F55: O | G55: O | H55: O | I55: O | J55: O | K55: X | L55: O | M55: O | N55: O | O55: X | P55: O | Q55: O | R55: O | S55: O | T55: X | U55: O | V55: X | W55: O | X55: X | Y55: X | Z55: O | AA55: O | AB55: =(COUNTIF(C55:AA55,"O")*2) -> 34 | AC55: =VLOOKUP(B55,'중1INTER(문법주관식)'!$B$2:$H$21,7,) -> 18 | AD55: =SUM(AB55:AC55) -> 52 | AI55: =(AB55/50) -> 0.68 | AJ55: =(AC55/20) -> 0.9
A56: 1INT | B56: 권시윤4513 | C56: X | D56: X | E56: O | F56: O | G56: O | H56: O | I56: O | J56: O | K56: O | L56: O | M56: O | N56: O | O56: O | P56: O | Q56: O | R56: O | S56: O | T56: O | U56: O | V56: X | W56: O | X56: X | Y56: X | Z56: O | AA56: X | AB56: =(COUNTIF(C56:AA56,"O")*2) -> 38 | AC56: =VLOOKUP(B56,'중1INTER(문법주관식)'!$B$2:$H$21,7,) -> 18 | AD56: =SUM(AB56:AC56) -> 56 | AI56: =(AB56/50) -> 0.76 | AJ56: =(AC56/20) -> 0.9
A57: 1INT | B57: 추연우2028 | C57: O | D57: X | E57: X | F57: O | G57: O | H57: O | I57: O | J57: O | K57: X | L57: X | M57: O | N57: O | O57: X | P57: X | Q57: X | R57: X | S57: O | T57: O | U57: O | V57: X | W57: O | X57: X | Y57: X | Z57: O | AA57: O | AB57: =(COUNTIF(C57:AA57,"O")*2) -> 28 | AC57: =VLOOKUP(B57,'중1INTER(문법주관식)'!$B$2:$H$21,7,) -> 14 | AD57: =SUM(AB57:AC57) -> 42 | AI57: =(AB57/50) -> 0.56 | AJ57: =(AC57/20) -> 0.7
A58: 1INT | B58: 오준서1498 | C58: X | D58: X | E58: X | F58: O | G58: X | H58: O | I58: X | J58: X | K58: X | L58: O | M58: O | N58: X | O58: X | P58: O | Q58: O | R58: X | S58: O | T58: O | U58: O | V58: O | W58: O | X58: X | Y58: X | Z58: O | AA58: X | AB58: =(COUNTIF(C58:AA58,"O")*2) -> 24 | AC58: =VLOOKUP(B58,'중1INTER(문법주관식)'!$B$2:$H$21,7,) -> 16 | AD58: =SUM(AB58:AC58) -> 40 | AI58: =(AB58/50) -> 0.48 | AJ58: =(AC58/20) -> 0.8
A59: 1INT | B59: 손채은1360 | C59: X | D59: X | E59: O | F59: O | G59: O | H59: O | I59: O | J59: O | K59: X | L59: O | M59: O | N59: O | O59: O | P59: O | Q59: O | R59: O | S59: X | T59: O | U59: O | V59: X | W59: O | X59: X | Y59: X | Z59: O | AA59: X | AB59: =(COUNTIF(C59:AA59,"O")*2) -> 34 | AC59: =VLOOKUP(B59,'중1INTER(문법주관식)'!$B$2:$H$21,7,) -> 12 | AD59: =SUM(AB59:AC59) -> 46 | AI59: =(AB59/50) -> 0.68 | AJ59: =(AC59/20) -> 0.6
A60: 1INT | B60: 박하루1937 | C60: X | D60: X | E60: X | F60: X | G60: X | H60: O | I60: X | J60: O | K60: O | L60: X | M60: O | N60: O | O60: X | P60: X | Q60: X | R60: O | S60: O | T60: X | U60: X | V60: X | W60: X | X60: X | Y60: X | Z60: O | AA60: X | AB60: =(COUNTIF(C60:AA60,"O")*2) -> 16 | AC60: =VLOOKUP(B60,'중1INTER(문법주관식)'!$B$2:$H$21,7,) -> 16 | AD60: =SUM(AB60:AC60) -> 32 | AI60: =(AB60/50) -> 0.32 | AJ60: =(AC60/20) -> 0.8
A61: 1INT | B61: 정시안4023 | C61: O | D61: X | E61: O | F61: X | G61: O | H61: O | I61: O | J61: O | K61: X | L61: O | M61: O | N61: O | O61: O | P61: O | Q61: O | R61: O | S61: O | T61: O | U61: O | V61: X | W61: X | X61: X | Y61: X | Z61: O | AA61: O | AB61: =(COUNTIF(C61:AA61,"O")*2) -> 36 | AC61: =VLOOKUP(B61,'중1INTER(문법주관식)'!$B$2:$H$21,7,) -> 18 | AD61: =SUM(AB61:AC61) -> 54 | AI61: =(AB61/50) -> 0.72 | AJ61: =(AC61/20) -> 0.9
A62: 1INT | B62: 조성하2402 | C62: X | D62: X | E62: X | F62: X | G62: O | H62: O | I62: O | J62: X | K62: X | L62: O | M62: O | N62: X | O62: X | P62: X | Q62: X | R62: X | S62: O | T62: X | U62: O | V62: X | W62: O | X62: X | Y62: X | Z62: O | AA62: X | AB62: =(COUNTIF(C62:AA62,"O")*2) -> 18 | AC62: =VLOOKUP(B62,'중1INTER(문법주관식)'!$B$2:$H$21,7,) -> 12 | AD62: =SUM(AB62:AC62) -> 30 | AI62: =(AB62/50) -> 0.36 | AJ62: =(AC62/20) -> 0.6
... A69: 1INT | B69: 이선엽3390 | C69: X | D69: X | E69: X | F69: O | G69: O | H69: O | I69: O | J69: X | K69: O | L69: O | M69: X | N69: O | O69: X | P69: O | Q69: X | R69: O | S69: O | T69: X | U69: O | V69: X | W69: O | X69: X | Y69: X | Z69: O | AA69: X | AB69: =(COUNTIF(C69:AA69,"O")*2) -> 26 | AC69: =VLOOKUP(B69,'중1INTER(문법주관식)'!$B$2:$H$21,7,) -> 18 | AD69: =SUM(AB69:AC69) -> 44 | AI69: =(AB69/50) -> 0.52 | AJ69: =(AC69/20) -> 0.9
A70: 1INT | B70: 고은기8177 | C70: O | D70: X | E70: X | F70: X | G70: O | H70: O | I70: O | J70: X | K70: O | L70: O | M70: O | N70: O | O70: O | P70: X | Q70: X | R70: X | S70: O | T70: O | U70: O | V70: O | W70: O | X70: X | Y70: X | Z70: X | AA70: X | AB70: =(COUNTIF(C70:AA70,"O")*2) -> 28 | AC70: =VLOOKUP(B70,'중1INTER(문법주관식)'!$B$2:$H$21,7,) -> 15 | AD70: =SUM(AB70:AC70) -> 43 | AE70: =AVERAGE(AD47:AD70) -> 41.625 | AI70: =(AB70/50) -> 0.56 | AJ70: =(AC70/20) -> 0.75
A73: 1AD | B73: 허은재9450 | C73: O | D73: X | E73: X | F73: O | G73: O | H73: O | I73: O | J73: X | K73: O | L73: O | M73: O | N73: O | O73: X | P73: X | Q73: X | R73: O | S73: O | T73: O | U73: O | V73: X | W73: O | X73: X | Y73: X | Z73: X | AA73: O | AB73: =(COUNTIF(C73:AA73,"O")*2) -> 30 | AC73: 내일 점수 확인해야 함 | AD73: =SUM(AB73:AC73) -> 30 | AI73: =(AB73/50) -> 0.6 | AJ73: =(AC73/20) -> #VALUE!
A74: 1AD | B74: 한준우9175 | C74: O | D74: O | E74: O | F74: O | G74: O | H74: O | I74: X | J74: X | K74: O | L74: O | M74: O | N74: O | O74: X | P74: X | Q74: O | R74: O | S74: O | T74: O | U74: O | V74: X | W74: O | X74: X | Y74: X | Z74: O | AA74: O | AB74: =(COUNTIF(C74:AA74,"O")*2) -> 36 | AC74: =VLOOKUP(B74,'중1AD(문법주관식)'!$B$2:$H$29,7,) -> 14 | AD74: =SUM(AB74:AC74) -> 50 | AI74: =(AB74/50) -> 0.72 | AJ74: =(AC74/20) -> 0.7
...

Sheet 중1(문법)(영역별 성취도)
D1: Be동사 | E1: Be동사 | F1: Be동사 | G1: Be동사 | H1: Be동사 | I1: Be동사 | J1: 일반동사 | K1: 일반동사 | L1: 일반동사 | M1: 일반동사 | N1: 일반동사 | O1: 일반동사 | P1: 일반동사 | Q1: 일반동사 | R1: 일반동사 | S1: 일반동사 | T1: 일반동사 | U1: 일반동사 | V1: 일반동사 | W1: 일반동사 | X1: 조동사 | Y1: 조동사 | Z1: 조동사 | AA1: 조동사 | AB1: 조동사 | AC1: Be동사 | AD1: 일반동사 | AE1: 조동사
A2: 반 | B2: 이름 | D2: Q25 | E2: Q21 | F2: Q17 | G2: Q10 | H2: Q7 | I2: Q2 | J2: Q3 | K2: Q4 | L2: Q5 | M2: Q8 | N2: Q11 | O2: Q12 | P2: Q13 | Q2: Q14 | R2: Q15 | S2: Q18 | T2: Q19 | U2: Q22 | V2: Q23 | W2: Q24 | X2: Q20 | Y2: Q16 | Z2: Q9 | AA2: Q6 | AB2: Q1 | AC2: 6 | AD2: 14 | AE2: 5
A3: 1FO | B3: 정다율4243 | D3: O | E3: X | F3: X | G3: O | H3: O | I3: O | J3: O | K3: O | L3: O | M3: O | N3: O | O3: O | P3: O | Q3: O | R3: X | S3: O | T3: O | U3: O | V3: O | W3: O | X3: O | Y3: O | Z3: O | AA3: O | AB3: X | AC3: =(COUNTIF(D3:I3,"O")/6) -> 0.66666667 | AD3: =(COUNTIF(J3:W3,"O")/14) -> 0.92857143 | AE3: =COUNTIF(X3:AB3,"O")/5 -> 0.8 | AG3: 1FO | AH3: Be동사 | AI3: 일반동사 | AJ3: 조동사 | AK3: .
A4: 1FO | B4: 최정우5267 | D4: X | E4: O | F4: O | G4: O | H4: O | I4: O | J4: O | K4: O | L4: O | M4: O | N4: O | O4: O | P4: O | Q4: O | R4: O | S4: O | T4: O | U4: X | V4: O | W4: X | X4: X | Y4: O | Z4: X | AA4: O | AB4: O | AC4: =(COUNTIF(D4:I4,"O")/6) -> 0.83333333 | AD4: =(COUNTIF(J4:W4,"O")/14) -> 0.85714286 | AE4: =COUNTIF(X4:AB4,"O")/5 -> 0.6 | AG4: 1INT | AH4: 시제 | AI4: 부정사 | AJ4: 동명사 | AK4: .
A5: 1FO | B5: 조하린9866 | D5: O | E5: O | F5: X | G5: O | H5: O | I5: X | J5: O | K5: O | L5: O | M5: O | N5: O | O5: O | P5: O | Q5: O | R5: O | S5: O | T5: O | U5: X | V5: O | W5: O | X5: O | Y5: O | Z5: O | AA5: O | AB5: O | AC5: =(COUNTIF(D5:I5,"O")/6) -> 0.66666667 | AD5: =(COUNTIF(J5:W5,"O")/14) -> 0.92857143 | AE5: =COUNTIF(X5:AB5,"O")/5 -> 1 | AG5: 1AD | AH5: 시제 | AI5: 부정사 | AJ5: 동명사 | AK5: .
A6: 1FO | B6: 조이플4632 | D6: O | E6: O | F6: O | G6: X | H6: O | I6: X | J6: X | K6: O | L6: O | M6: X | N6: O | O6: O | P6: O | Q6: O | R6: O | S6: X | T6: O | U6: X | V6: O | W6: O | X6: O | Y6: O | Z6: O | AA6: O | AB6: X | AC6: =(COUNTIF(D6:I6,"O")/6) -> 0.66666667 | AD6: =(COUNTIF(J6:W6,"O")/14) -> 0.71428571 | AE6: =COUNTIF(X6:AB6,"O")/5 -> 0.8 | AG6: IVY | AH6: 완료시제 | AI6: 수동태 | AJ6: 비교 | AK6: 접속사
A7: 1FO | B7: 한가인6162 | D7: X | E7: O | F7: X | G7: O | H7: O | I7: O | J7: O | K7: O | L7: O | M7: O | N7: O | O7: O | P7: O | Q7: O | R7: X | S7: O | T7: O | U7: O | V7: X | W7: X | X7: O | Y7: O | Z7: O | AA7: O | AB7: O | AC7: =(COUNTIF(D7:I7,"O")/6) -> 0.66666667 | AD7: =(COUNTIF(J7:W7,"O")/14) -> 0.78571429 | AE7: =COUNTIF(X7:AB7,"O")/5 -> 1
A8: 1FO | B8: 정준우7962 | D8: X | E8: O | F8: O | G8: O | H8: O | I8: O | J8: O | K8: O | L8: O | M8: O | N8: O | O8: O | P8: O | Q8: O | R8: O | S8: O | T8: O | U8: O | V8: X | W8: O | X8: O | Y8: O | Z8: O | AA8: O | AB8: O | AC8: =(COUNTIF(D8:I8,"O")/6) -> 0.83333333 | AD8: =(COUNTIF(J8:W8,"O")/14) -> 0.92857143 | AE8: =COUNTIF(X8:AB8,"O")/5 -> 1
A9: 1FO | B9: 김주하2492 | D9: O | E9: O | F9: O | G9: O | H9: O | I9: O | J9: O | K9: O | L9: O | M9: O | N9: O | O9: O | P9: X | Q9: O | R9: O | S9: X | T9: O | U9: X | V9: O | W9: X | X9: O | Y9: O | Z9: O | AA9: O | AB9: O | AC9: =(COUNTIF(D9:I9,"O")/6) -> 1 | AD9: =(COUNTIF(J9:W9,"O")/14) -> 0.71428571 | AE9: =COUNTIF(X9:AB9,"O")/5 -> 1
A10: 1FO | B10: 김상우2835 | D10: O | E10: O | F10: X | G10: X | H10: O | I10: O | J10: O | K10: O | L10: O | M10: X | N10: O | O10: O | P10: O | Q10: O | R10: X | S10: X | T10: X | U10: O | V10: X | W10: X | X10: O | Y10: X | Z10: O | AA10: X | AB10: X | AC10: =(COUNTIF(D10:I10,"O")/6) -> 0.66666667 | AD10: =(COUNTIF(J10:W10,"O")/14) -> 0.57142857 | AE10: =COUNTIF(X10:AB10,"O")/5 -> 0.4
A11: 1FO | B11: 심효주0430 | D11: X | E11: X | F11: X | G11: O | H11: O | I11: X | J11: X | K11: X | L11: X | M11: X | N11: O | O11: O | P11: X | Q11: X | R11: X | S11: X | T11: X | U11: X | V11: O | W11: X | X11: X | Y11: O | Z11: X | AA11: O | AB11: X | AC11: =(COUNTIF(D11:I11,"O")/6) -> 0.33333333 | AD11: =(COUNTIF(J11:W11,"O")/14) -> 0.21428571 | AE11: =COUNTIF(X11:AB11,"O")/5 -> 0.4
A12: 1FO | B12: 김유민0779 | D12: O | E12: O | F12: X | G12: O | H12: O | I12: O | J12: O | K12: O | L12: O | M12: O | N12: O | O12: O | P12: O | Q12: O | R12: O | S12: X | T12: O | U12: X | V12: O | W12: X | X12: X | Y12: O | Z12: X | AA12: O | AB12: O | AC12: =(COUNTIF(D12:I12,"O")/6) -> 0.83333333 | AD12: =(COUNTIF(J12:W12,"O")/14) -> 0.78571429 | AE12: =COUNTIF(X12:AB12,"O")/5 -> 0.6
A13: 1FO | B13: 이우진8720 | D13: O | E13: O | F13: O | G13: O | H13: O | I13: O | J13: O | K13: O | L13: O | M13: O | N13: O | O13: O | P13: O | Q13: O | R13: X | S13: X | T13: O | U13: X | V13: X | W13: X | X13: O | Y13: X | Z13: X | AA13: O | AB13: X | AC13: =(COUNTIF(D13:I13,"O")/6) -> 1 | AD13: =(COUNTIF(J13:W13,"O")/14) -> 0.64285714 | AE13: =COUNTIF(X13:AB13,"O")/5 -> 0.4
A14: 1FO | B14: 정유빈9239 | D14: X | E14: O | F14: O | G14: O | H14: O | I14: O | J14: O | K14: O | L14: O | M14: O | N14: O | O14: O | P14: O | Q14: X | R14: X | S14: X | T14: O | U14: O | V14: X | W14: O | X14: O | Y14: O | Z14: X | AA14: O | AB14: O | AC14: =(COUNTIF(D14:I14,"O")/6) -> 0.83333333 | AD14: =(COUNTIF(J14:W14,"O")/14) -> 0.71428571 | AE14: =COUNTIF(X14:AB14,"O")/5 -> 0.8
A15: 1FO | B15: 최아정6445 | D15: O | E15: O | F15: O | G15: O | H15: O | I15: O | J15: O | K15: O | L15: O | M15: O | N15: O | O15: O | P15: O | Q15: O | R15: O | S15: O | T15: O | U15: X | V15: O | W15: O | X15: O | Y15: O | Z15: O | AA15: O | AB15: O | AC15: =(COUNTIF(D15:I15,"O")/6) -> 1 | AD15: =(COUNTIF(J15:W15,"O")/14) -> 0.92857143 | AE15: =COUNTIF(X15:AB15,"O")/5 -> 1
A16: 1FO | B16: 오수진5052 | D16: O | E16: X | F16: X | G16: X | H16: X | I16: X | J16: O | K16: O | L16: O | M16: O | N16: O | O16: O | P16: X | Q16: O | R16: X | S16: X | T16: X | U16: X | V16: O | W16: O | X16: O | Y16: O | Z16: X | AA16: X | AB16: O | AC16: =(COUNTIF(D16:I16,"O")/6) -> 0.16666667 | AD16: =(COUNTIF(J16:W16,"O")/14) -> 0.64285714 | AE16: =COUNTIF(X16:AB16,"O")/5 -> 0.6
A17: 1FO | B17: 이시우1234 | D17: O | E17: O | F17: O | G17: O | H17: O | I17: O | J17: O | K17: O | L17: O | M17: O | N17: O | O17: O | P17: O | Q17: O | R17: X | S17: O | T17: O | U17: O | V17: X | W17: O | X17: O | Y17: O | Z17: X | AA17: O | AB17: O | AC17: =(COUNTIF(D17:I17,"O")/6) -> 1 | AD17: =(COUNTIF(J17:W17,"O")/14) -> 0.85714286 | AE17: =COUNTIF(X17:AB17,"O")/5 -> 0.8
A18: 1FO | B18: 김은성1571 | D18: X | E18: X | F18: X | G18: O | H18: O | I18: O | J18: O | K18: X | L18: O | M18: O | N18: O | O18: O | P18: X | Q18: X | R18: X | S18: X | T18: O | U18: O | V18: X | W18: X | X18: O | Y18: X | Z18: X | AA18: X | AB18: O | AC18: =(COUNTIF(D18:I18,"O")/6) -> 0.5 | AD18: =(COUNTIF(J18:W18,"O")/14) -> 0.5 | AE18: =COUNTIF(X18:AB18,"O")/5 -> 0.4
... A44: 1FO | B44: 최황지7291 | D44: O | E44: X | F44: X | G44: X | H44: O | I44: O | J44: O | K44: O | L44: O | M44: O | N44: O | O44: O | P44: O | Q44: O | R44: X | S44: X | T44: O | U44: X | V44: O | W44: X | X44: O | Y44: O | Z44: X | AA44: O | AB44: O | AC44: =(COUNTIF(D44:I44,"O")/6) -> 0.5 | AD44: =(COUNTIF(J44:W44,"O")/14) -> 0.71428571 | AE44: =COUNTIF(X44:AB44,"O")/5 -> 0.8
AC45: 6 | AD45: 13 | AE45: 6
D46: 시제 | E46: 시제 | F46: 시제 | G46: 시제 | H46: 시제 | I46: 시제 | J46: 부정사 | K46: 부정사 | L46: 부정사 | M46: 부정사 | N46: 부정사 | O46: 부정사 | P46: 부정사 | Q46: 부정사 | R46: 부정사 | S46: 부정사 | T46: 부정사 | U46: 부정사 | V46: 부정사 | W46: 동명사 | X46: 동명사 | Y46: 동명사 | Z46: 동명사 | AA46: 동명사 | AB46: 동명사 | AC46: 시제 | AD46: 부정사 | AE46: 동명사
A47: 1INT | B47: 손지원1266 | D47: O | E47: O | F47: O | G47: O | H47: O | I47: O | J47: O | K47: O | L47: O | M47: O | N47: O | O47: O | P47: O | Q47: X | R47: O | S47: O | T47: O | U47: O | V47: O | W47: O | X47: O | Y47: O | Z47: O | AA47: O | AB47: O | AC47: =(COUNTIF(D47:I47,"O")/6) -> 1 | AD47: =(COUNTIF(J47:V47,"O")/13) -> 0.92307692 | AE47: =COUNTIF(W47:AB47,"O")/6 -> 1
A48: 1INT | B48: 이윤오2947 | D48: O | E48: X | F48: X | G48: X | H48: O | I48: O | J48: X | K48: X | L48: X | M48: X | N48: O | O48: O | P48: O | Q48: O | R48: X | S48: O | T48: O | U48: X | V48: X | W48: O | X48: O | Y48: O | Z48: X | AA48: X | AB48: O | AC48: =(COUNTIF(D48:I48,"O")/6) -> 0.5 | AD48: =(COUNTIF(J48:V48,"O")/13) -> 0.46153846 | AE48: =COUNTIF(W48:AB48,"O")/6 -> 0.66666667
A49: 1INT | B49: 손현겸3726 | D49: O | E49: O | F49: X | G49: X | H49: O | I49: O | J49: X | K49: X | L49: X | M49: X | N49: O | O49: X | P49: O | Q49: X | R49: O | S49: O | T49: O | U49: X | V49: X | W49: O | X49: X | Y49: O | Z49: O | AA49: O | AB49: X | AC49: =(COUNTIF(D49:I49,"O")/6) -> 0.66666667 | AD49: =(COUNTIF(J49:V49,"O")/13) -> 0.38461538 | AE49: =COUNTIF(W49:AB49,"O")/6 -> 0.66666667
A50: 1INT | B50: 이소영6515 | D50: X | E50: X | F50: X | G50: X | H50: O | I50: O | J50: O | K50: X | L50: X | M50: X | N50: O | O50: O | P50: X | Q50: X | R50: X | S50: O | T50: O | U50: O | V50: O | W50: O | X50: O | Y50: X | Z50: O | AA50: X | AB50: O | AC50: =(COUNTIF(D50:I50,"O")/6) -> 0.33333333 | AD50: =(COUNTIF(J50:V50,"O")/13) -> 0.53846154 | AE50: =COUNTIF(W50:AB50,"O")/6 -> 0.66666667
A51: 1INT | B51: 이준희2280 | D51: X | E51: O | F51: X | G51: O | H51: X | I51: O | J51: X | K51: O | L51: X | M51: X | N51: X | O51: O | P51: X | Q51: O | R51: X | S51: O | T51: X | U51: X | V51: X | W51: O | X51: X | Y51: X | Z51: X | AA51: X | AB51: X | AC51: =(COUNTIF(D51:I51,"O")/6) -> 0.5 | AD51: =(COUNTIF(J51:V51,"O")/13) -> 0.30769231 | AE51: =COUNTIF(W51:AB51,"O")/6 -> 0.16666667
A52: 1INT | B52: 유주원4257 | D52: O | E52: X | F52: O | G52: X | H52: O | I52: O | J52: O | K52: X | L52: X | M52: O | N52: O | O52: O | P52: O | Q52: O | R52: X | S52: O | T52: O | U52: X | V52: O | W52: O | X52: O | Y52: O | Z52: O | AA52: O | AB52: O | AC52: =(COUNTIF(D52:I52,"O")/6) -> 0.66666667 | AD52: =(COUNTIF(J52:V52,"O")/13) -> 0.69230769 | AE52: =COUNTIF(W52:AB52,"O")/6 -> 1
A53: 1INT | B53: 신준우9838 | D53: X | E53: X | F53: O | G53: X | H53: O | I53: O | J53: X | K53: O | L53: X | M53: O | N53: O | O53: O | P53: O | Q53: X | R53: O | S53: O | T53: X | U53: X | V53: O | W53: O | X53: O | Y53: X | Z53: X | AA53: O | AB53: O | AC53: =(COUNTIF(D53:I53,"O")/6) -> 0.5 | AD53: =(COUNTIF(J53:V53,"O")/13) -> 0.61538462 | AE53: =COUNTIF(W53:AB53,"O")/6 -> 0.66666667
A54: 1INT | B54: 유태형0555 | D54: O | E54: O | F54: X | G54: X | H54: O | I54: O | J54: X | K54: X | L54: X | M54: O | N54: O | O54: O | P54: O | Q54: X | R54: O | S54: X | T54: O | U54: X | V54: X | W54: O | X54: O | Y54: O | Z54: X | AA54: X | AB54: O | AC54: =(COUNTIF(D54:I54,"O")/6) -> 0.66666667 | AD54: =(COUNTIF(J54:V54,"O")/13) -> 0.46153846 | AE54: =COUNTIF(W54:AB54,"O")/6 -> 0.66666667
